Workbook

Sheet Instrucciones
A1: Hoja | B1: Uso
A2: Instrucciones | B2: Explica el funcionamiento de la plantilla.
A3: Mapa_RA_CE | B3: Define qué RA/CE trata cada actividad. Usa 1 si aplica o un peso parcial como 0.5.
A4: Calificaciones | B4: Introduce Alumno, Actividad y Nota. Las columnas RA/CE se rellenan automáticamente según Mapa_RA_CE.
A5: Resumen_RA_CE | B5: Introduce la lista de alumnado en la columna A para calcular medias por RA/CE.
A6: RA_CE | B6: Referencia textual de resultados de aprendizaje y criterios de evaluación.
A8: Regla práctica | B8: Si una práctica trata un CE, la nota se copia en ese CE. Si usas pesos parciales en Mapa_RA_CE, se copia Nota x peso.
A9: Importante | B9: La plantilla es una base docente: ajusta el mapa de actividades cuando cambie una práctica o rúbrica.

Sheet Mapa_RA_CE
A1: Actividad | B1: Unidad | C1: Tipo | D1: Peso actividad | E1: Estado | F1: Descripción | G1: RA1 | H1: RA1.a | I1: RA1.b | J1: RA1.c | K1: RA1.d | L1: RA1.e | M1: RA1.f | N1: RA2 | O1: RA2.a | P1: RA2.b | Q1: RA2.c | R1: RA2.d | S1: RA2.e | T1: RA3 | U1: RA3.a | V1: RA3.b | W1: RA3.c | X1: RA3.d | Y1: RA3.e | Z1: RA4 | AA1: RA4.a | AB1: RA4.b | AC1: RA4.c | AD1: RA4.d
A2: UD1 - Práctica Python y NumPy | B2: 01-fundamentos-python | C2: Práctica | D2: 1 | E2: Activa | F2: Sintaxis, estructuras, funciones, NumPy/JAX inicial. | G2: 1 | H2: 1 | I2: 1 | K2: 1 | L2: 1
A3: UD1 - Comparativa de lenguajes y formatos para IA | B3: 01-fundamentos-python | C3: Actividad breve | D3: 1 | E3: Recomendada | F3: Evidencia formal de idoneidad de lenguajes y formatos de intercambio. | G3: 1 | I3: 1 | J3: 1 | K3: 1 | L3: 1 | M3: 1
A4: UD2 - EDA y tratamiento de datos | B4: 02-tratamiento-datos | C4: Práctica | D4: 1 | E4: Activa | F4: Limpieza, transformación, análisis exploratorio y visualización. | N4: 1 | Q4: 1 | R4: 1 | S4: 1
A5: UD3 - Dataset y modelado ML | B5: 03-machine-learning | C5: Laboratorio/proyecto | D5: 1 | E5: Activa | F5: Creación de dataset, entrenamiento, evaluación y entrega de modelo. | N5: 1 | P5: 1 | Q5: 1 | R5: 1 | S5: 1
A6: UD4 - Laboratorio Deep Learning | B6: 04-deep-learning | C6: Laboratorio | D6: 1 | E6: Activa | F6: Redes neuronales, frameworks, entrenamiento y evaluación. | N6: 1 | P6: 1 | Q6: 1 | R6: 1 | S6: 1
A7: UD5 - Comparativa Cloud/MLOps | B7: 05-cloud-mlops | C7: Tarea | D7: 1 | E7: Activa | F7: Plataformas, servicios, feature stores, cloud y MLOps. | N7: 1 | O7: 1 | P7: 1 | T7: 1 | V7: 1 | W7: 1 | X7: 1
A8: UD6 - APIs, RAG y agentes | B8: 06-llm-agentes | C8: Práctica | D8: 1 | E8: Activa | F8: Serving, APIs, RAG, agentes, evaluación y trazabilidad. | N8: 1 | O8: 1 | R8: 1 | S8: 1 | T8: 1 | V8: 1 | W8: 1 | X8: 1
A9: UD7 - Proyecto de convergencia de herramientas IA | B9: 07-convergencia-herramientas | C9: Proyecto | D9: 1 | E9: Activa | F9: Pipeline completo: datos, MLflow, Prefect, FastAPI, RAG/agentes, observabilidad e IA responsable. | N9: 1 | R9: 1 | S9: 1 | T9: 1 | U9: 1 | V9: 1 | W9: 1 | X9: 1 | Y9: 1 | Z9: 1 | AC9: 1 | AD9: 1
A10: UD8 - Visión artificial y XAI | B10: 08-vision-xai | C10: Práctica | D10: 1 | E10: Activa | F10: Segmentación, tracking, métricas, LIME/SHAP/Grad-CAM. | N10: 1 | Q10: 1 | R10: 1 | S10: 1
A11: UD9 - GPU, dashboard y pipeline | B11: 09-gpu-avanzado | C11: Proyecto | D11: 1 | E11: Activa | F11: RAPIDS/JAX, benchmark CPU/GPU, dashboard y pipeline reproducible. | N11: 1 | P11: 1 | R11: 1 | S11: 1 | T11: 1 | V11: 1 | W11: 1 | Y11: 1 | Z11: 1 | AC11: 1 | AD11: 1
A12: UD10 - Series temporales y forecasting | B12: 10-series-temporales | C12: Taller/proyecto | D12: 1 | E12: Activa | F12: Baselines, modelos, métricas, forecasting y análisis temporal. | N12: 1 | Q12: 1 | R12: 1 | S12: 1 | T12: 1 | Y12: 1
A13: UD12 - Proyecto final integrado | B13: 12-proyecto-integrado | C13: Proyecto final | D13: 1 | E13: Activa | F13: Problema real, dos fuentes de datos, componente IA/ML, salida útil, documentación y defensa. | N13: 1 | Q13: 1 | R13: 1 | S13: 1 | T13: 1 | U13: 1 | V13: 1 | W13: 1 | X13: 1 | Y13: 1 | Z13: 1 | AA13: 1 | AB13: 1 | AC13: 1 | AD13: 1

Sheet Calificaciones
A1: Alumno | B1: Actividad | C1: Unidad | D1: Nota 0-10 | E1: Observaciones | F1: RA1 | G1: RA1.a | H1: RA1.b | I1: RA1.c | J1: RA1.d | K1: RA1.e | L1: RA1.f | M1: RA2 | N1: RA2.a | O1: RA2.b | P1: RA2.c | Q1: RA2.d | R1: RA2.e | S1: RA3 | T1: RA3.a | U1: RA3.b | V1: RA3.c | W1: RA3.d | X1: RA3.e | Y1: RA4 | Z1: RA4.a | AA1: RA4.b | AB1: RA4.c | AC1: RA4.d
C2: =IFERROR(VLOOKUP($B2,Mapa_RA_CE!$A:$AD,2,FALSE),"") | F2: =IFERROR(IF(VLOOKUP($B2,Mapa_RA_CE!$A:$AD,MATCH(F1,Mapa_RA_CE!$1:$1,0),FALSE)>0,$D2*VLOOKUP($B2,Mapa_RA_CE!$A:$AD,MATCH(F1,Mapa_RA_CE!$1:$1,0),FALSE),""),"") | G2: =IFERROR(IF(VLOOKUP($B2,Mapa_RA_CE!$A:$AD,MATCH(G1,Mapa_RA_CE!$1:$1,0),FALSE)>0,$D2*VLOOKUP($B2,Mapa_RA_CE!$A:$AD,MATCH(G1,Mapa_RA_CE!$1:$1,0),FALSE),""),"") | H2: =IFERROR(IF(VLOOKUP($B2,Mapa_RA_CE!$A:$AD,MATCH(H1,Mapa_RA_CE!$1:$1,0),FALSE)>0,$D2*VLOOKUP($B2,Mapa_RA_CE!$A:$AD,MATCH(H1,Mapa_RA_CE!$1:$1,0),FALSE),""),"") | I2: =IFERROR(IF(VLOOKUP($B2,Mapa_RA_CE!$A:$AD,MATCH(I1,Mapa_RA_CE!$1:$1,0),FALSE)>0,$D2*VLOOKUP($B2,Mapa_RA_CE!$A:$AD,MATCH(I1,Mapa_RA_CE!$1:$1,0),FALSE),""),"") | J2: =IFERROR(IF(VLOOKUP($B2,Mapa_RA_CE!$A:$AD,MATCH(J1,Mapa_RA_CE!$1:$1,0),FALSE)>0,$D2*VLOOKUP($B2,Mapa_RA_CE!$A:$AD,MATCH(J1,Mapa_RA_CE!$1:$1,0),FALSE),""),"") | K2: =IFERROR(IF(VLOOKUP($B2,Mapa_RA_CE!$A:$AD,MATCH(K1,Mapa_RA_CE!$1:$1,0),FALSE)>0,$D2*VLOOKUP($B2,Mapa_RA_CE!$A:$AD,MATCH(K1,Mapa_RA_CE!$1:$1,0),FALSE),""),"") | L2: =IFERROR(IF(VLOOKUP($B2,Mapa_RA_CE!$A:$AD,MATCH(L1,Mapa_RA_CE!$1:$1,0),FALSE)>0,$D2*VLOOKUP($B2,Mapa_RA_CE!$A:$AD,MATCH(L1,Mapa_RA_CE!$1:$1,0),FALSE),""),"") | M2: =IFERROR(IF(VLOOKUP($B2,Mapa_RA_CE!$A:$AD,MATCH(M1,Mapa_RA_CE!$1:$1,0),FALSE)>0,$D2*VLOOKUP($B2,Mapa_RA_CE!$A:$AD,MATCH(M1,Mapa_RA_CE!$1:$1,0),FALSE),""),"") | ... AC2: =IFERROR(IF(VLOOKUP($B2,Mapa_RA_CE!$A:$AD,MATCH(AC1,Mapa_RA_CE!$1:$1,0),FALSE)>0,$D2*VLOOKUP($B2,Mapa_RA_CE!$A:$AD,MATCH(AC1,Mapa_RA_CE!$1:$1,0),FALSE),""),"")
C3: =IFERROR(VLOOKUP($B3,Mapa_RA_CE!$A:$AD,2,FALSE),"") | F3: =IFERROR(IF(VLOOKUP($B3,Mapa_RA_CE!$A:$AD,MATCH(F1,Mapa_RA_CE!$1:$1,0),FALSE)>0,$D3*VLOOKUP($B3,Mapa_RA_CE!$A:$AD,MATCH(F1,Mapa_RA_CE!$1:$1,0),FALSE),""),"") | G3: =IFERROR(IF(VLOOKUP($B3,Mapa_RA_CE!$A:$AD,MATCH(G1,Mapa_RA_CE!$1:$1,0),FALSE)>0,$D3*VLOOKUP($B3,Mapa_RA_CE!$A:$AD,MATCH(G1,Mapa_RA_CE!$1:$1,0),FALSE),""),"") | H3: =IFERROR(IF(VLOOKUP($B3,Mapa_RA_CE!$A:$AD,MATCH(H1,Mapa_RA_CE!$1:$1,0),FALSE)>0,$D3*VLOOKUP($B3,Mapa_RA_CE!$A:$AD,MATCH(H1,Mapa_RA_CE!$1:$1,0),FALSE),""),"") | I3: =IFERROR(IF(VLOOKUP($B3,Mapa_RA_CE!$A:$AD,MATCH(I1,Mapa_RA_CE!$1:$1,0),FALSE)>0,$D3*VLOOKUP($B3,Mapa_RA_CE!$A:$AD,MATCH(I1,Mapa_RA_CE!$1:$1,0),FALSE),""),"") | J3: =IFERROR(IF(VLOOKUP($B3,Mapa_RA_CE!$A:$AD,MATCH(J1,Mapa_RA_CE!$1:$1,0),FALSE)>0,$D3*VLOOKUP($B3,Mapa_RA_CE!$A:$AD,MATCH(J1,Mapa_RA_CE!$1:$1,0),FALSE),""),"") | K3: =IFERROR(IF(VLOOKUP($B3,Mapa_RA_CE!$A:$AD,MATCH(K1,Mapa_RA_CE!$1:$1,0),FALSE)>0,$D3*VLOOKUP($B3,Mapa_RA_CE!$A:$AD,MATCH(K1,Mapa_RA_CE!$1:$1,0),FALSE),""),"") | L3: =IFERROR(IF(VLOOKUP($B3,Mapa_RA_CE!$A:$AD,MATCH(L1,Mapa_RA_CE!$1:$1,0),FALSE)>0,$D3*VLOOKUP($B3,Mapa_RA_CE!$A:$AD,MATCH(L1,Mapa_RA_CE!$1:$1,0),FALSE),""),"") | M3: =IFERROR(IF(VLOOKUP($B3,Mapa_RA_CE!$A:$AD,MATCH(M1,Mapa_RA_CE!$1:$1,0),FALSE)>0,$D3*VLOOKUP($B3,Mapa_RA_CE!$A:$AD,MATCH(M1,Mapa_RA_CE!$1:$1,0),FALSE),""),"") | ... AC3: =IFERROR(IF(VLOOKUP($B3,Mapa_RA_CE!$A:$AD,MATCH(AC1,Mapa_RA_CE!$1:$1,0),FALSE)>0,$D3*VLOOKUP($B3,Mapa_RA_CE!$A:$AD,MATCH(AC1,Mapa_RA_CE!$1:$1,0),FALSE),""),"")
C4: =IFERROR(VLOOKUP($B4,Mapa_RA_CE!$A:$AD,2,FALSE),"") | F4: =IFERROR(IF(VLOOKUP($B4,Mapa_RA_CE!$A:$AD,MATCH(F1,Mapa_RA_CE!$1:$1,0),FALSE)>0,$D4*VLOOKUP($B4,Mapa_RA_CE!$A:$AD,MATCH(F1,Mapa_RA_CE!$1:$1,0),FALSE),""),"") | G4: =IFERROR(IF(VLOOKUP($B4,Mapa_RA_CE!$A:$AD,MATCH(G1,Mapa_RA_CE!$1:$1,0),FALSE)>0,$D4*VLOOKUP($B4,Mapa_RA_CE!$A:$AD,MATCH(G1,Mapa_RA_CE!$1:$1,0),FALSE),""),"") | H4: =IFERROR(IF(VLOOKUP($B4,Mapa_RA_CE!$A:$AD,MATCH(H1,Mapa_RA_CE!$1:$1,0),FALSE)>0,$D4*VLOOKUP($B4,Mapa_RA_CE!$A:$AD,MATCH(H1,Mapa_RA_CE!$1:$1,0),FALSE),""),"") | I4: =IFERROR(IF(VLOOKUP($B4,Mapa_RA_CE!$A:$AD,MATCH(I1,Mapa_RA_CE!$1:$1,0),FALSE)>0,$D4*VLOOKUP($B4,Mapa_RA_CE!$A:$AD,MATCH(I1,Mapa_RA_CE!$1:$1,0),FALSE),""),"") | J4: =IFERROR(IF(VLOOKUP($B4,Mapa_RA_CE!$A:$AD,MATCH(J1,Mapa_RA_CE!$1:$1,0),FALSE)>0,$D4*VLOOKUP($B4,Mapa_RA_CE!$A:$AD,MATCH(J1,Mapa_RA_CE!$1:$1,0),FALSE),""),"") | K4: =IFERROR(IF(VLOOKUP($B4,Mapa_RA_CE!$A:$AD,MATCH(K1,Mapa_RA_CE!$1:$1,0),FALSE)>0,$D4*VLOOKUP($B4,Mapa_RA_CE!$A:$AD,MATCH(K1,Mapa_RA_CE!$1:$1,0),FALSE),""),"") | L4: =IFERROR(IF(VLOOKUP($B4,Mapa_RA_CE!$A:$AD,MATCH(L1,Mapa_RA_CE!$1:$1,0),FALSE)>0,$D4*VLOOKUP($B4,Mapa_RA_CE!$A:$AD,MATCH(L1,Mapa_RA_CE!$1:$1,0),FALSE),""),"") | M4: =IFERROR(IF(VLOOKUP($B4,Mapa_RA_CE!$A:$AD,MATCH(M1,Mapa_RA_CE!$1:$1,0),FALSE)>0,$D4*VLOOKUP($B4,Mapa_RA_CE!$A:$AD,MATCH(M1,Mapa_RA_CE!$1:$1,0),FALSE),""),"") | ... AC4: =IFERROR(IF(VLOOKUP($B4,Mapa_RA_CE!$A:$AD,MATCH(AC1,Mapa_RA_CE!$1:$1,0),FALSE)>0,$D4*VLOOKUP($B4,Mapa_RA_CE!$A:$AD,MATCH(AC1,Mapa_RA_CE!$1:$1,0),FALSE),""),"")
C5: =IFERROR(VLOOKUP($B5,Mapa_RA_CE!$A:$AD,2,FALSE),"") | F5: =IFERROR(IF(VLOOKUP($B5,Mapa_RA_CE!$A:$AD,MATCH(F1,Mapa_RA_CE!$1:$1,0),FALSE)>0,$D5*VLOOKUP($B5,Mapa_RA_CE!$A:$AD,MATCH(F1,Mapa_RA_CE!$1:$1,0),FALSE),""),"") | G5: =IFERROR(IF(VLOOKUP($B5,Mapa_RA_CE!$A:$AD,MATCH(G1,Mapa_RA_CE!$1:$1,0),FALSE)>0,$D5*VLOOKUP($B5,Mapa_RA_CE!$A:$AD,MATCH(G1,Mapa_RA_CE!$1:$1,0),FALSE),""),"") | H5: =IFERROR(IF(VLOOKUP($B5,Mapa_RA_CE!$A:$AD,MATCH(H1,Mapa_RA_CE!$1:$1,0),FALSE)>0,$D5*VLOOKUP($B5,Mapa_RA_CE!$A:$AD,MATCH(H1,Mapa_RA_CE!$1:$1,0),FALSE),""),"") | I5: =IFERROR(IF(VLOOKUP($B5,Mapa_RA_CE!$A:$AD,MATCH(I1,Mapa_RA_CE!$1:$1,0),FALSE)>0,$D5*VLOOKUP($B5,Mapa_RA_CE!$A:$AD,MATCH(I1,Mapa_RA_CE!$1:$1,0),FALSE),""),"") | J5: =IFERROR(IF(VLOOKUP($B5,Mapa_RA_CE!$A:$AD,MATCH(J1,Mapa_RA_CE!$1:$1,0),FALSE)>0,$D5*VLOOKUP($B5,Mapa_RA_CE!$A:$AD,MATCH(J1,Mapa_RA_CE!$1:$1,0),FALSE),""),"") | K5: =IFERROR(IF(VLOOKUP($B5,Mapa_RA_CE!$A:$AD,MATCH(K1,Mapa_RA_CE!$1:$1,0),FALSE)>0,$D5*VLOOKUP($B5,Mapa_RA_CE!$A:$AD,MATCH(K1,Mapa_RA_CE!$1:$1,0),FALSE),""),"") | L5: =IFERROR(IF(VLOOKUP($B5,Mapa_RA_CE!$A:$AD,MATCH(L1,Mapa_RA_CE!$1:$1,0),FALSE)>0,$D5*VLOOKUP($B5,Mapa_RA_CE!$A:$AD,MATCH(L1,Mapa_RA_CE!$1:$1,0),FALSE),""),"") | M5: =IFERROR(IF(VLOOKUP($B5,Mapa_RA_CE!$A:$AD,MATCH(M1,Mapa_RA_CE!$1:$1,0),FALSE)>0,$D5*VLOOKUP($B5,Mapa_RA_CE!$A:$AD,MATCH(M1,Mapa_RA_CE!$1:$1,0),FALSE),""),"") | ... AC5: =IFERROR(IF(VLOOKUP($B5,Mapa_RA_CE!$A:$AD,MATCH(AC1,Mapa_RA_CE!$1:$1,0),FALSE)>0,$D5*VLOOKUP($B5,Mapa_RA_CE!$A:$AD,MATCH(AC1,Mapa_RA_CE!$1:$1,0),FALSE),""),"")
C6: =IFERROR(VLOOKUP($B6,Mapa_RA_CE!$A:$AD,2,FALSE),"") | F6: =IFERROR(IF(VLOOKUP($B6,Mapa_RA_CE!$A:$AD,MATCH(F1,Mapa_RA_CE!$1:$1,0),FALSE)>0,$D6*VLOOKUP($B6,Mapa_RA_CE!$A:$AD,MATCH(F1,Mapa_RA_CE!$1:$1,0),FALSE),""),"") | G6: =IFERROR(IF(VLOOKUP($B6,Mapa_RA_CE!$A:$AD,MATCH(G1,Mapa_RA_CE!$1:$1,0),FALSE)>0,$D6*VLOOKUP($B6,Mapa_RA_CE!$A:$AD,MATCH(G1,Mapa_RA_CE!$1:$1,0),FALSE),""),"") | H6: =IFERROR(IF(VLOOKUP($B6,Mapa_RA_CE!$A:$AD,MATCH(H1,Mapa_RA_CE!$1:$1,0),FALSE)>0,$D6*VLOOKUP($B6,Mapa_RA_CE!$A:$AD,MATCH(H1,Mapa_RA_CE!$1:$1,0),FALSE),""),"") | I6: =IFERROR(IF(VLOOKUP($B6,Mapa_RA_CE!$A:$AD,MATCH(I1,Mapa_RA_CE!$1:$1,0),FALSE)>0,$D6*VLOOKUP($B6,Mapa_RA_CE!$A:$AD,MATCH(I1,Mapa_RA_CE!$1:$1,0),FALSE),""),"") | J6: =IFERROR(IF(VLOOKUP($B6,Mapa_RA_CE!$A:$AD,MATCH(J1,Mapa_RA_CE!$1:$1,0),FALSE)>0,$D6*VLOOKUP($B6,Mapa_RA_CE!$A:$AD,MATCH(J1,Mapa_RA_CE!$1:$1,0),FALSE),""),"") | K6: =IFERROR(IF(VLOOKUP($B6,Mapa_RA_CE!$A:$AD,MATCH(K1,Mapa_RA_CE!$1:$1,0),FALSE)>0,$D6*VLOOKUP($B6,Mapa_RA_CE!$A:$AD,MATCH(K1,Mapa_RA_CE!$1:$1,0),FALSE),""),"") | L6: =IFERROR(IF(VLOOKUP($B6,Mapa_RA_CE!$A:$AD,MATCH(L1,Mapa_RA_CE!$1:$1,0),FALSE)>0,$D6*VLOOKUP($B6,Mapa_RA_CE!$A:$AD,MATCH(L1,Mapa_RA_CE!$1:$1,0),FALSE),""),"") | M6: =IFERROR(IF(VLOOKUP($B6,Mapa_RA_CE!$A:$AD,MATCH(M1,Mapa_RA_CE!$1:$1,0),FALSE)>0,$D6*VLOOKUP($B6,Mapa_RA_CE!$A:$AD,MATCH(M1,Mapa_RA_CE!$1:$1,0),FALSE),""),"") | ... AC6: =IFERROR(IF(VLOOKUP($B6,Mapa_RA_CE!$A:$AD,MATCH(AC1,Mapa_RA_CE!$1:$1,0),FALSE)>0,$D6*VLOOKUP($B6,Mapa_RA_CE!$A:$AD,MATCH(AC1,Mapa_RA_CE!$1:$1,0),FALSE),""),"")
C7: =IFERROR(VLOOKUP($B7,Mapa_RA_CE!$A:$AD,2,FALSE),"") | F7: =IFERROR(IF(VLOOKUP($B7,Mapa_RA_CE!$A:$AD,MATCH(F1,Mapa_RA_CE!$1:$1,0),FALSE)>0,$D7*VLOOKUP($B7,Mapa_RA_CE!$A:$AD,MATCH(F1,Mapa_RA_CE!$1:$1,0),FALSE),""),"") | G7: =IFERROR(IF(VLOOKUP($B7,Mapa_RA_CE!$A:$AD,MATCH(G1,Mapa_RA_CE!$1:$1,0),FALSE)>0,$D7*VLOOKUP($B7,Mapa_RA_CE!$A:$AD,MATCH(G1,Mapa_RA_CE!$1:$1,0),FALSE),""),"") | H7: =IFERROR(IF(VLOOKUP($B7,Mapa_RA_CE!$A:$AD,MATCH(H1,Mapa_RA_CE!$1:$1,0),FALSE)>0,$D7*VLOOKUP($B7,Mapa_RA_CE!$A:$AD,MATCH(H1,Mapa_RA_CE!$1:$1,0),FALSE),""),"") | I7: =IFERROR(IF(VLOOKUP($B7,Mapa_RA_CE!$A:$AD,MATCH(I1,Mapa_RA_CE!$1:$1,0),FALSE)>0,$D7*VLOOKUP($B7,Mapa_RA_CE!$A:$AD,MATCH(I1,Mapa_RA_CE!$1:$1,0),FALSE),""),"") | J7: =IFERROR(IF(VLOOKUP($B7,Mapa_RA_CE!$A:$AD,MATCH(J1,Mapa_RA_CE!$1:$1,0),FALSE)>0,$D7*VLOOKUP($B7,Mapa_RA_CE!$A:$AD,MATCH(J1,Mapa_RA_CE!$1:$1,0),FALSE),""),"") | K7: =IFERROR(IF(VLOOKUP($B7,Mapa_RA_CE!$A:$AD,MATCH(K1,Mapa_RA_CE!$1:$1,0),FALSE)>0,$D7*VLOOKUP($B7,Mapa_RA_CE!$A:$AD,MATCH(K1,Mapa_RA_CE!$1:$1,0),FALSE),""),"") | L7: =IFERROR(IF(VLOOKUP($B7,Mapa_RA_CE!$A:$AD,MATCH(L1,Mapa_RA_CE!$1:$1,0),FALSE)>0,$D7*VLOOKUP($B7,Mapa_RA_CE!$A:$AD,MATCH(L1,Mapa_RA_CE!$1:$1,0),FALSE),""),"") | M7: =IFERROR(IF(VLOOKUP($B7,Mapa_RA_CE!$A:$AD,MATCH(M1,Mapa_RA_CE!$1:$1,0),FALSE)>0,$D7*VLOOKUP($B7,Mapa_RA_CE!$A:$AD,MATCH(M1,Mapa_RA_CE!$1:$1,0),FALSE),""),"") | ... AC7: =IFERROR(IF(VLOOKUP($B7,Mapa_RA_CE!$A:$AD,MATCH(AC1,Mapa_RA_CE!$1:$1,0),FALSE)>0,$D7*VLOOKUP($B7,Mapa_RA_CE!$A:$AD,MATCH(AC1,Mapa_RA_CE!$1:$1,0),FALSE),""),"")
C8: =IFERROR(VLOOKUP($B8,Mapa_RA_CE!$A:$AD,2,FALSE),"") | F8: =IFERROR(IF(VLOOKUP($B8,Mapa_RA_CE!$A:$AD,MATCH(F1,Mapa_RA_CE!$1:$1,0),FALSE)>0,$D8*VLOOKUP($B8,Mapa_RA_CE!$A:$AD,MATCH(F1,Mapa_RA_CE!$1:$1,0),FALSE),""),"") | G8: =IFERROR(IF(VLOOKUP($B8,Mapa_RA_CE!$A:$AD,MATCH(G1,Mapa_RA_CE!$1:$1,0),FALSE)>0,$D8*VLOOKUP($B8,Mapa_RA_CE!$A:$AD,MATCH(G1,Mapa_RA_CE!$1:$1,0),FALSE),""),"") | H8: =IFERROR(IF(VLOOKUP($B8,Mapa_RA_CE!$A:$AD,MATCH(H1,Mapa_RA_CE!$1:$1,0),FALSE)>0,$D8*VLOOKUP($B8,Mapa_RA_CE!$A:$AD,MATCH(H1,Mapa_RA_CE!$1:$1,0),FALSE),""),"") | I8: =IFERROR(IF(VLOOKUP($B8,Mapa_RA_CE!$A:$AD,MATCH(I1,Mapa_RA_CE!$1:$1,0),FALSE)>0,$D8*VLOOKUP($B8,Mapa_RA_CE!$A:$AD,MATCH(I1,Mapa_RA_CE!$1:$1,0),FALSE),""),"") | J8: =IFERROR(IF(VLOOKUP($B8,Mapa_RA_CE!$A:$AD,MATCH(J1,Mapa_RA_CE!$1:$1,0),FALSE)>0,$D8*VLOOKUP($B8,Mapa_RA_CE!$A:$AD,MATCH(J1,Mapa_RA_CE!$1:$1,0),FALSE),""),"") | K8: =IFERROR(IF(VLOOKUP($B8,Mapa_RA_CE!$A:$AD,MATCH(K1,Mapa_RA_CE!$1:$1,0),FALSE)>0,$D8*VLOOKUP($B8,Mapa_RA_CE!$A:$AD,MATCH(K1,Mapa_RA_CE!$1:$1,0),FALSE),""),"") | L8: =IFERROR(IF(VLOOKUP($B8,Mapa_RA_CE!$A:$AD,MATCH(L1,Mapa_RA_CE!$1:$1,0),FALSE)>0,$D8*VLOOKUP($B8,Mapa_RA_CE!$A:$AD,MATCH(L1,Mapa_RA_CE!$1:$1,0),FALSE),""),"") | M8: =IFERROR(IF(VLOOKUP($B8,Mapa_RA_CE!$A:$AD,MATCH(M1,Mapa_RA_CE!$1:$1,0),FALSE)>0,$D8*VLOOKUP($B8,Mapa_RA_CE!$A:$AD,MATCH(M1,Mapa_RA_CE!$1:$1,0),FALSE),""),"") | ... AC8: =IFERROR(IF(VLOOKUP($B8,Mapa_RA_CE!$A:$AD,MATCH(AC1,Mapa_RA_CE!$1:$1,0),FALSE)>0,$D8*VLOOKUP($B8,Mapa_RA_CE!$A:$AD,MATCH(AC1,Mapa_RA_CE!$1:$1,0),FALSE),""),"")
C9: =IFERROR(VLOOKUP($B9,Mapa_RA_CE!$A:$AD,2,FALSE),"") | F9: =IFERROR(IF(VLOOKUP($B9,Mapa_RA_CE!$A:$AD,MATCH(F1,Mapa_RA_CE!$1:$1,0),FALSE)>0,$D9*VLOOKUP($B9,Mapa_RA_CE!$A:$AD,MATCH(F1,Mapa_RA_CE!$1:$1,0),FALSE),""),"") | G9: =IFERROR(IF(VLOOKUP($B9,Mapa_RA_CE!$A:$AD,MATCH(G1,Mapa_RA_CE!$1:$1,0),FALSE)>0,$D9*VLOOKUP($B9,Mapa_RA_CE!$A:$AD,MATCH(G1,Mapa_RA_CE!$1:$1,0),FALSE),""),"") | H9: =IFERROR(IF(VLOOKUP($B9,Mapa_RA_CE!$A:$AD,MATCH(H1,Mapa_RA_CE!$1:$1,0),FALSE)>0,$D9*VLOOKUP($B9,Mapa_RA_CE!$A:$AD,MATCH(H1,Mapa_RA_CE!$1:$1,0),FALSE),""),"") | I9: =IFERROR(IF(VLOOKUP($B9,Mapa_RA_CE!$A:$AD,MATCH(I1,Mapa_RA_CE!$1:$1,0),FALSE)>0,$D9*VLOOKUP($B9,Mapa_RA_CE!$A:$AD,MATCH(I1,Mapa_RA_CE!$1:$1,0),FALSE),""),"") | J9: =IFERROR(IF(VLOOKUP($B9,Mapa_RA_CE!$A:$AD,MATCH(J1,Mapa_RA_CE!$1:$1,0),FALSE)>0,$D9*VLOOKUP($B9,Mapa_RA_CE!$A:$AD,MATCH(J1,Mapa_RA_CE!$1:$1,0),FALSE),""),"") | K9: =IFERROR(IF(VLOOKUP($B9,Mapa_RA_CE!$A:$AD,MATCH(K1,Mapa_RA_CE!$1:$1,0),FALSE)>0,$D9*VLOOKUP($B9,Mapa_RA_CE!$A:$AD,MATCH(K1,Mapa_RA_CE!$1:$1,0),FALSE),""),"") | L9: =IFERROR(IF(VLOOKUP($B9,Mapa_RA_CE!$A:$AD,MATCH(L1,Mapa_RA_CE!$1:$1,0),FALSE)>0,$D9*VLOOKUP($B9,Mapa_RA_CE!$A:$AD,MATCH(L1,Mapa_RA_CE!$1:$1,0),FALSE),""),"") | M9: =IFERROR(IF(VLOOKUP($B9,Mapa_RA_CE!$A:$AD,MATCH(M1,Mapa_RA_CE!$1:$1,0),FALSE)>0,$D9*VLOOKUP($B9,Mapa_RA_CE!$A:$AD,MATCH(M1,Mapa_RA_CE!$1:$1,0),FALSE),""),"") | ... AC9: =IFERROR(IF(VLOOKUP($B9,Mapa_RA_CE!$A:$AD,MATCH(AC1,Mapa_RA_CE!$1:$1,0),FALSE)>0,$D9*VLOOKUP($B9,Mapa_RA_CE!$A:$AD,MATCH(AC1,Mapa_RA_CE!$1:$1,0),FALSE),""),"")
C10: =IFERROR(VLOOKUP($B10,Mapa_RA_CE!$A:$AD,2,FALSE),"") | F10: =IFERROR(IF(VLOOKUP($B10,Mapa_RA_CE!$A:$AD,MATCH(F1,Mapa_RA_CE!$1:$1,0),FALSE)>0,$D10*VLOOKUP($B10,Mapa_RA_CE!$A:$AD,MATCH(F1,Mapa_RA_CE!$1:$1,0),FALSE),""),"") | G10: =IFERROR(IF(VLOOKUP($B10,Mapa_RA_CE!$A:$AD,MATCH(G1,Mapa_RA_CE!$1:$1,0),FALSE)>0,$D10*VLOOKUP($B10,Mapa_RA_CE!$A:$AD,MATCH(G1,Mapa_RA_CE!$1:$1,0),FALSE),""),"") | H10: =IFERROR(IF(VLOOKUP($B10,Mapa_RA_CE!$A:$AD,MATCH(H1,Mapa_RA_CE!$1:$1,0),FALSE)>0,$D10*VLOOKUP($B10,Mapa_RA_CE!$A:$AD,MATCH(H1,Mapa_RA_CE!$1:$1,0),FALSE),""),"") | I10: =IFERROR(IF(VLOOKUP($B10,Mapa_RA_CE!$A:$AD,MATCH(I1,Mapa_RA_CE!$1:$1,0),FALSE)>0,$D10*VLOOKUP($B10,Mapa_RA_CE!$A:$AD,MATCH(I1,Mapa_RA_CE!$1:$1,0),FALSE),""),"") | J10: =IFERROR(IF(VLOOKUP($B10,Mapa_RA_CE!$A:$AD,MATCH(J1,Mapa_RA_CE!$1:$1,0),FALSE)>0,$D10*VLOOKUP($B10,Mapa_RA_CE!$A:$AD,MATCH(J1,Mapa_RA_CE!$1:$1,0),FALSE),""),"") | K10: =IFERROR(IF(VLOOKUP($B10,Mapa_RA_CE!$A:$AD,MATCH(K1,Mapa_RA_CE!$1:$1,0),FALSE)>0,$D10*VLOOKUP($B10,Mapa_RA_CE!$A:$AD,MATCH(K1,Mapa_RA_CE!$1:$1,0),FALSE),""),"") | L10: =IFERROR(IF(VLOOKUP($B10,Mapa_RA_CE!$A:$AD,MATCH(L1,Mapa_RA_CE!$1:$1,0),FALSE)>0,$D10*VLOOKUP($B10,Mapa_RA_CE!$A:$AD,MATCH(L1,Mapa_RA_CE!$1:$1,0),FALSE),""),"") | M10: =IFERROR(IF(VLOOKUP($B10,Mapa_RA_CE!$A:$AD,MATCH(M1,Mapa_RA_CE!$1:$1,0),FALSE)>0,$D10*VLOOKUP($B10,Mapa_RA_CE!$A:$AD,MATCH(M1,Mapa_RA_CE!$1:$1,0),FALSE),""),"") | ... AC10: =IFERROR(IF(VLOOKUP($B10,Mapa_RA_CE!$A:$AD,MATCH(AC1,Mapa_RA_CE!$1:$1,0),FALSE)>0,$D10*VLOOKUP($B10,Mapa_RA_CE!$A:$AD,MATCH(AC1,Mapa_RA_CE!$1:$1,0),FALSE),""),"")
C11: =IFERROR(VLOOKUP($B11,Mapa_RA_CE!$A:$AD,2,FALSE),"") | F11: =IFERROR(IF(VLOOKUP($B11,Mapa_RA_CE!$A:$AD,MATCH(F1,Mapa_RA_CE!$1:$1,0),FALSE)>0,$D11*VLOOKUP($B11,Mapa_RA_CE!$A:$AD,MATCH(F1,Mapa_RA_CE!$1:$1,0),FALSE),""),"") | G11: =IFERROR(IF(VLOOKUP($B11,Mapa_RA_CE!$A:$AD,MATCH(G1,Mapa_RA_CE!$1:$1,0),FALSE)>0,$D11*VLOOKUP($B11,Mapa_RA_CE!$A:$AD,MATCH(G1,Mapa_RA_CE!$1:$1,0),FALSE),""),"") | H11: =IFERROR(IF(VLOOKUP($B11,Mapa_RA_CE!$A:$AD,MATCH(H1,Mapa_RA_CE!$1:$1,0),FALSE)>0,$D11*VLOOKUP($B11,Mapa_RA_CE!$A:$AD,MATCH(H1,Mapa_RA_CE!$1:$1,0),FALSE),""),"") | I11: =IFERROR(IF(VLOOKUP($B11,Mapa_RA_CE!$A:$AD,MATCH(I1,Mapa_RA_CE!$1:$1,0),FALSE)>0,$D11*VLOOKUP($B11,Mapa_RA_CE!$A:$AD,MATCH(I1,Mapa_RA_CE!$1:$1,0),FALSE),""),"") | J11: =IFERROR(IF(VLOOKUP($B11,Mapa_RA_CE!$A:$AD,MATCH(J1,Mapa_RA_CE!$1:$1,0),FALSE)>0,$D11*VLOOKUP($B11,Mapa_RA_CE!$A:$AD,MATCH(J1,Mapa_RA_CE!$1:$1,0),FALSE),""),"") | K11: =IFERROR(IF(VLOOKUP($B11,Mapa_RA_CE!$A:$AD,MATCH(K1,Mapa_RA_CE!$1:$1,0),FALSE)>0,$D11*VLOOKUP($B11,Mapa_RA_CE!$A:$AD,MATCH(K1,Mapa_RA_CE!$1:$1,0),FALSE),""),"") | L11: =IFERROR(IF(VLOOKUP($B11,Mapa_RA_CE!$A:$AD,MATCH(L1,Mapa_RA_CE!$1:$1,0),FALSE)>0,$D11*VLOOKUP($B11,Mapa_RA_CE!$A:$AD,MATCH(L1,Mapa_RA_CE!$1:$1,0),FALSE),""),"") | M11: =IFERROR(IF(VLOOKUP($B11,Mapa_RA_CE!$A:$AD,MATCH(M1,Mapa_RA_CE!$1:$1,0),FALSE)>0,$D11*VLOOKUP($B11,Mapa_RA_CE!$A:$AD,MATCH(M1,Mapa_RA_CE!$1:$1,0),FALSE),""),"") | ... AC11: =IFERROR(IF(VLOOKUP($B11,Mapa_RA_CE!$A:$AD,MATCH(AC1,Mapa_RA_CE!$1:$1,0),FALSE)>0,$D11*VLOOKUP($B11,Mapa_RA_CE!$A:$AD,MATCH(AC1,Mapa_RA_CE!$1:$1,0),FALSE),""),"")
C12: =IFERROR(VLOOKUP($B12,Mapa_RA_CE!$A:$AD,2,FALSE),"") | F12: =IFERROR(IF(VLOOKUP($B12,Mapa_RA_CE!$A:$AD,MATCH(F1,Mapa_RA_CE!$1:$1,0),FALSE)>0,$D12*VLOOKUP($B12,Mapa_RA_CE!$A:$AD,MATCH(F1,Mapa_RA_CE!$1:$1,0),FALSE),""),"") | G12: =IFERROR(IF(VLOOKUP($B12,Mapa_RA_CE!$A:$AD,MATCH(G1,Mapa_RA_CE!$1:$1,0),FALSE)>0,$D12*VLOOKUP($B12,Mapa_RA_CE!$A:$AD,MATCH(G1,Mapa_RA_CE!$1:$1,0),FALSE),""),"") | H12: =IFERROR(IF(VLOOKUP($B12,Mapa_RA_CE!$A:$AD,MATCH(H1,Mapa_RA_CE!$1:$1,0),FALSE)>0,$D12*VLOOKUP($B12,Mapa_RA_CE!$A:$AD,MATCH(H1,Mapa_RA_CE!$1:$1,0),FALSE),""),"") | I12: =IFERROR(IF(VLOOKUP($B12,Mapa_RA_CE!$A:$AD,MATCH(I1,Mapa_RA_CE!$1:$1,0),FALSE)>0,$D12*VLOOKUP($B12,Mapa_RA_CE!$A:$AD,MATCH(I1,Mapa_RA_CE!$1:$1,0),FALSE),""),"") | J12: =IFERROR(IF(VLOOKUP($B12,Mapa_RA_CE!$A:$AD,MATCH(J1,Mapa_RA_CE!$1:$1,0),FALSE)>0,$D12*VLOOKUP($B12,Mapa_RA_CE!$A:$AD,MATCH(J1,Mapa_RA_CE!$1:$1,0),FALSE),""),"") | K12: =IFERROR(IF(VLOOKUP($B12,Mapa_RA_CE!$A:$AD,MATCH(K1,Mapa_RA_CE!$1:$1,0),FALSE)>0,$D12*VLOOKUP($B12,Mapa_RA_CE!$A:$AD,MATCH(K1,Mapa_RA_CE!$1:$1,0),FALSE),""),"") | L12: =IFERROR(IF(VLOOKUP($B12,Mapa_RA_CE!$A:$AD,MATCH(L1,Mapa_RA_CE!$1:$1,0),FALSE)>0,$D12*VLOOKUP($B12,Mapa_RA_CE!$A:$AD,MATCH(L1,Mapa_RA_CE!$1:$1,0),FALSE),""),"") | M12: =IFERROR(IF(VLOOKUP($B12,Mapa_RA_CE!$A:$AD,MATCH(M1,Mapa_RA_CE!$1:$1,0),FALSE)>0,$D12*VLOOKUP($B12,Mapa_RA_CE!$A:$AD,MATCH(M1,Mapa_RA_CE!$1:$1,0),FALSE),""),"") | ... AC12: =IFERROR(IF(VLOOKUP($B12,Mapa_RA_CE!$A:$AD,MATCH(AC1,Mapa_RA_CE!$1:$1,0),FALSE)>0,$D12*VLOOKUP($B12,Mapa_RA_CE!$A:$AD,MATCH(AC1,Mapa_RA_CE!$1:$1,0),FALSE),""),"")
C13: =IFERROR(VLOOKUP($B13,Mapa_RA_CE!$A:$AD,2,FALSE),"") | F13: =IFERROR(IF(VLOOKUP($B13,Mapa_RA_CE!$A:$AD,MATCH(F1,Mapa_RA_CE!$1:$1,0),FALSE)>0,$D13*VLOOKUP($B13,Mapa_RA_CE!$A:$AD,MATCH(F1,Mapa_RA_CE!$1:$1,0),FALSE),""),"") | G13: =IFERROR(IF(VLOOKUP($B13,Mapa_RA_CE!$A:$AD,MATCH(G1,Mapa_RA_CE!$1:$1,0),FALSE)>0,$D13*VLOOKUP($B13,Mapa_RA_CE!$A:$AD,MATCH(G1,Mapa_RA_CE!$1:$1,0),FALSE),""),"") | H13: =IFERROR(IF(VLOOKUP($B13,Mapa_RA_CE!$A:$AD,MATCH(H1,Mapa_RA_CE!$1:$1,0),FALSE)>0,$D13*VLOOKUP($B13,Mapa_RA_CE!$A:$AD,MATCH(H1,Mapa_RA_CE!$1:$1,0),FALSE),""),"") | I13: =IFERROR(IF(VLOOKUP($B13,Mapa_RA_CE!$A:$AD,MATCH(I1,Mapa_RA_CE!$1:$1,0),FALSE)>0,$D13*VLOOKUP($B13,Mapa_RA_CE!$A:$AD,MATCH(I1,Mapa_RA_CE!$1:$1,0),FALSE),""),"") | J13: =IFERROR(IF(VLOOKUP($B13,Mapa_RA_CE!$A:$AD,MATCH(J1,Mapa_RA_CE!$1:$1,0),FALSE)>0,$D13*VLOOKUP($B13,Mapa_RA_CE!$A:$AD,MATCH(J1,Mapa_RA_CE!$1:$1,0),FALSE),""),"") | K13: =IFERROR(IF(VLOOKUP($B13,Mapa_RA_CE!$A:$AD,MATCH(K1,Mapa_RA_CE!$1:$1,0),FALSE)>0,$D13*VLOOKUP($B13,Mapa_RA_CE!$A:$AD,MATCH(K1,Mapa_RA_CE!$1:$1,0),FALSE),""),"") | L13: =IFERROR(IF(VLOOKUP($B13,Mapa_RA_CE!$A:$AD,MATCH(L1,Mapa_RA_CE!$1:$1,0),FALSE)>0,$D13*VLOOKUP($B13,Mapa_RA_CE!$A:$AD,MATCH(L1,Mapa_RA_CE!$1:$1,0),FALSE),""),"") | M13: =IFERROR(IF(VLOOKUP($B13,Mapa_RA_CE!$A:$AD,MATCH(M1,Mapa_RA_CE!$1:$1,0),FALSE)>0,$D13*VLOOKUP($B13,Mapa_RA_CE!$A:$AD,MATCH(M1,Mapa_RA_CE!$1:$1,0),FALSE),""),"") | ... AC13: =IFERROR(IF(VLOOKUP($B13,Mapa_RA_CE!$A:$AD,MATCH(AC1,Mapa_RA_CE!$1:$1,0),FALSE)>0,$D13*VLOOKUP($B13,Mapa_RA_CE!$A:$AD,MATCH(AC1,Mapa_RA_CE!$1:$1,0),FALSE),""),"")
C14: =IFERROR(VLOOKUP($B14,Mapa_RA_CE!$A:$AD,2,FALSE),"") | F14: =IFERROR(IF(VLOOKUP($B14,Mapa_RA_CE!$A:$AD,MATCH(F1,Mapa_RA_CE!$1:$1,0),FALSE)>0,$D14*VLOOKUP($B14,Mapa_RA_CE!$A:$AD,MATCH(F1,Mapa_RA_CE!$1:$1,0),FALSE),""),"") | G14: =IFERROR(IF(VLOOKUP($B14,Mapa_RA_CE!$A:$AD,MATCH(G1,Mapa_RA_CE!$1:$1,0),FALSE)>0,$D14*VLOOKUP($B14,Mapa_RA_CE!$A:$AD,MATCH(G1,Mapa_RA_CE!$1:$1,0),FALSE),""),"") | H14: =IFERROR(IF(VLOOKUP($B14,Mapa_RA_CE!$A:$AD,MATCH(H1,Mapa_RA_CE!$1:$1,0),FALSE)>0,$D14*VLOOKUP($B14,Mapa_RA_CE!$A:$AD,MATCH(H1,Mapa_RA_CE!$1:$1,0),FALSE),""),"") | I14: =IFERROR(IF(VLOOKUP($B14,Mapa_RA_CE!$A:$AD,MATCH(I1,Mapa_RA_CE!$1:$1,0),FALSE)>0,$D14*VLOOKUP($B14,Mapa_RA_CE!$A:$AD,MATCH(I1,Mapa_RA_CE!$1:$1,0),FALSE),""),"") | J14: =IFERROR(IF(VLOOKUP($B14,Mapa_RA_CE!$A:$AD,MATCH(J1,Mapa_RA_CE!$1:$1,0),FALSE)>0,$D14*VLOOKUP($B14,Mapa_RA_CE!$A:$AD,MATCH(J1,Mapa_RA_CE!$1:$1,0),FALSE),""),"") | K14: =IFERROR(IF(VLOOKUP($B14,Mapa_RA_CE!$A:$AD,MATCH(K1,Mapa_RA_CE!$1:$1,0),FALSE)>0,$D14*VLOOKUP($B14,Mapa_RA_CE!$A:$AD,MATCH(K1,Mapa_RA_CE!$1:$1,0),FALSE),""),"") | L14: =IFERROR(IF(VLOOKUP($B14,Mapa_RA_CE!$A:$AD,MATCH(L1,Mapa_RA_CE!$1:$1,0),FALSE)>0,$D14*VLOOKUP($B14,Mapa_RA_CE!$A:$AD,MATCH(L1,Mapa_RA_CE!$1:$1,0),FALSE),""),"") | M14: =IFERROR(IF(VLOOKUP($B14,Mapa_RA_CE!$A:$AD,MATCH(M1,Mapa_RA_CE!$1:$1,0),FALSE)>0,$D14*VLOOKUP($B14,Mapa_RA_CE!$A:$AD,MATCH(M1,Mapa_RA_CE!$1:$1,0),FALSE),""),"") | ... AC14: =IFERROR(IF(VLOOKUP($B14,Mapa_RA_CE!$A:$AD,MATCH(AC1,Mapa_RA_CE!$1:$1,0),FALSE)>0,$D14*VLOOKUP($B14,Mapa_RA_CE!$A:$AD,MATCH(AC1,Mapa_RA_CE!$1:$1,0),FALSE),""),"")
C15: =IFERROR(VLOOKUP($B15,Mapa_RA_CE!$A:$AD,2,FALSE),"") | F15: =IFERROR(IF(VLOOKUP($B15,Mapa_RA_CE!$A:$AD,MATCH(F1,Mapa_RA_CE!$1:$1,0),FALSE)>0,$D15*VLOOKUP($B15,Mapa_RA_CE!$A:$AD,MATCH(F1,Mapa_RA_CE!$1:$1,0),FALSE),""),"") | G15: =IFERROR(IF(VLOOKUP($B15,Mapa_RA_CE!$A:$AD,MATCH(G1,Mapa_RA_CE!$1:$1,0),FALSE)>0,$D15*VLOOKUP($B15,Mapa_RA_CE!$A:$AD,MATCH(G1,Mapa_RA_CE!$1:$1,0),FALSE),""),"") | H15: =IFERROR(IF(VLOOKUP($B15,Mapa_RA_CE!$A:$AD,MATCH(H1,Mapa_RA_CE!$1:$1,0),FALSE)>0,$D15*VLOOKUP($B15,Mapa_RA_CE!$A:$AD,MATCH(H1,Mapa_RA_CE!$1:$1,0),FALSE),""),"") | I15: =IFERROR(IF(VLOOKUP($B15,Mapa_RA_CE!$A:$AD,MATCH(I1,Mapa_RA_CE!$1:$1,0),FALSE)>0,$D15*VLOOKUP($B15,Mapa_RA_CE!$A:$AD,MATCH(I1,Mapa_RA_CE!$1:$1,0),FALSE),""),"") | J15: =IFERROR(IF(VLOOKUP($B15,Mapa_RA_CE!$A:$AD,MATCH(J1,Mapa_RA_CE!$1:$1,0),FALSE)>0,$D15*VLOOKUP($B15,Mapa_RA_CE!$A:$AD,MATCH(J1,Mapa_RA_CE!$1:$1,0),FALSE),""),"") | K15: =IFERROR(IF(VLOOKUP($B15,Mapa_RA_CE!$A:$AD,MATCH(K1,Mapa_RA_CE!$1:$1,0),FALSE)>0,$D15*VLOOKUP($B15,Mapa_RA_CE!$A:$AD,MATCH(K1,Mapa_RA_CE!$1:$1,0),FALSE),""),"") | L15: =IFERROR(IF(VLOOKUP($B15,Mapa_RA_CE!$A:$AD,MATCH(L1,Mapa_RA_CE!$1:$1,0),FALSE)>0,$D15*VLOOKUP($B15,Mapa_RA_CE!$A:$AD,MATCH(L1,Mapa_RA_CE!$1:$1,0),FALSE),""),"") | M15: =IFERROR(IF(VLOOKUP($B15,Mapa_RA_CE!$A:$AD,MATCH(M1,Mapa_RA_CE!$1:$1,0),FALSE)>0,$D15*VLOOKUP($B15,Mapa_RA_CE!$A:$AD,MATCH(M1,Mapa_RA_CE!$1:$1,0),FALSE),""),"") | ... AC15: =IFERROR(IF(VLOOKUP($B15,Mapa_RA_CE!$A:$AD,MATCH(AC1,Mapa_RA_CE!$1:$1,0),FALSE)>0,$D15*VLOOKUP($B15,Mapa_RA_CE!$A:$AD,MATCH(AC1,Mapa_RA_CE!$1:$1,0),FALSE),""),"")
C16: =IFERROR(VLOOKUP($B16,Mapa_RA_CE!$A:$AD,2,FALSE),"") | F16: =IFERROR(IF(VLOOKUP($B16,Mapa_RA_CE!$A:$AD,MATCH(F1,Mapa_RA_CE!$1:$1,0),FALSE)>0,$D16*VLOOKUP($B16,Mapa_RA_CE!$A:$AD,MATCH(F1,Mapa_RA_CE!$1:$1,0),FALSE),""),"") | G16: =IFERROR(IF(VLOOKUP($B16,Mapa_RA_CE!$A:$AD,MATCH(G1,Mapa_RA_CE!$1:$1,0),FALSE)>0,$D16*VLOOKUP($B16,Mapa_RA_CE!$A:$AD,MATCH(G1,Mapa_RA_CE!$1:$1,0),FALSE),""),"") | H16: =IFERROR(IF(VLOOKUP($B16,Mapa_RA_CE!$A:$AD,MATCH(H1,Mapa_RA_CE!$1:$1,0),FALSE)>0,$D16*VLOOKUP($B16,Mapa_RA_CE!$A:$AD,MATCH(H1,Mapa_RA_CE!$1:$1,0),FALSE),""),"") | I16: =IFERROR(IF(VLOOKUP($B16,Mapa_RA_CE!$A:$AD,MATCH(I1,Mapa_RA_CE!$1:$1,0),FALSE)>0,$D16*VLOOKUP($B16,Mapa_RA_CE!$A:$AD,MATCH(I1,Mapa_RA_CE!$1:$1,0),FALSE),""),"") | J16: =IFERROR(IF(VLOOKUP($B16,Mapa_RA_CE!$A:$AD,MATCH(J1,Mapa_RA_CE!$1:$1,0),FALSE)>0,$D16*VLOOKUP($B16,Mapa_RA_CE!$A:$AD,MATCH(J1,Mapa_RA_CE!$1:$1,0),FALSE),""),"") | K16: =IFERROR(IF(VLOOKUP($B16,Mapa_RA_CE!$A:$AD,MATCH(K1,Mapa_RA_CE!$1:$1,0),FALSE)>0,$D16*VLOOKUP($B16,Mapa_RA_CE!$A:$AD,MATCH(K1,Mapa_RA_CE!$1:$1,0),FALSE),""),"") | L16: =IFERROR(IF(VLOOKUP($B16,Mapa_RA_CE!$A:$AD,MATCH(L1,Mapa_RA_CE!$1:$1,0),FALSE)>0,$D16*VLOOKUP($B16,Mapa_RA_CE!$A:$AD,MATCH(L1,Mapa_RA_CE!$1:$1,0),FALSE),""),"") | M16: =IFERROR(IF(VLOOKUP($B16,Mapa_RA_CE!$A:$AD,MATCH(M1,Mapa_RA_CE!$1:$1,0),FALSE)>0,$D16*VLOOKUP($B16,Mapa_RA_CE!$A:$AD,MATCH(M1,Mapa_RA_CE!$1:$1,0),FALSE),""),"") | ... AC16: =IFERROR(IF(VLOOKUP($B16,Mapa_RA_CE!$A:$AD,MATCH(AC1,Mapa_RA_CE!$1:$1,0),FALSE)>0,$D16*VLOOKUP($B16,Mapa_RA_CE!$A:$AD,MATCH(AC1,Mapa_RA_CE!$1:$1,0),FALSE),""),"")
C17: =IFERROR(VLOOKUP($B17,Mapa_RA_CE!$A:$AD,2,FALSE),"") | F17: =IFERROR(IF(VLOOKUP($B17,Mapa_RA_CE!$A:$AD,MATCH(F1,Mapa_RA_CE!$1:$1,0),FALSE)>0,$D17*VLOOKUP($B17,Mapa_RA_CE!$A:$AD,MATCH(F1,Mapa_RA_CE!$1:$1,0),FALSE),""),"") | G17: =IFERROR(IF(VLOOKUP($B17,Mapa_RA_CE!$A:$AD,MATCH(G1,Mapa_RA_CE!$1:$1,0),FALSE)>0,$D17*VLOOKUP($B17,Mapa_RA_CE!$A:$AD,MATCH(G1,Mapa_RA_CE!$1:$1,0),FALSE),""),"") | H17: =IFERROR(IF(VLOOKUP($B17,Mapa_RA_CE!$A:$AD,MATCH(H1,Mapa_RA_CE!$1:$1,0),FALSE)>0,$D17*VLOOKUP($B17,Mapa_RA_CE!$A:$AD,MATCH(H1,Mapa_RA_CE!$1:$1,0),FALSE),""),"") | I17: =IFERROR(IF(VLOOKUP($B17,Mapa_RA_CE!$A:$AD,MATCH(I1,Mapa_RA_CE!$1:$1,0),FALSE)>0,$D17*VLOOKUP($B17,Mapa_RA_CE!$A:$AD,MATCH(I1,Mapa_RA_CE!$1:$1,0),FALSE),""),"") | J17: =IFERROR(IF(VLOOKUP($B17,Mapa_RA_CE!$A:$AD,MATCH(J1,Mapa_RA_CE!$1:$1,0),FALSE)>0,$D17*VLOOKUP($B17,Mapa_RA_CE!$A:$AD,MATCH(J1,Mapa_RA_CE!$1:$1,0),FALSE),""),"") | K17: =IFERROR(IF(VLOOKUP($B17,Mapa_RA_CE!$A:$AD,MATCH(K1,Mapa_RA_CE!$1:$1,0),FALSE)>0,$D17*VLOOKUP($B17,Mapa_RA_CE!$A:$AD,MATCH(K1,Mapa_RA_CE!$1:$1,0),FALSE),""),"") | L17: =IFERROR(IF(VLOOKUP($B17,Mapa_RA_CE!$A:$AD,MATCH(L1,Mapa_RA_CE!$1:$1,0),FALSE)>0,$D17*VLOOKUP($B17,Mapa_RA_CE!$A:$AD,MATCH(L1,Mapa_RA_CE!$1:$1,0),FALSE),""),"") | M17: =IFERROR(IF(VLOOKUP($B17,Mapa_RA_CE!$A:$AD,MATCH(M1,Mapa_RA_CE!$1:$1,0),FALSE)>0,$D17*VLOOKUP($B17,Mapa_RA_CE!$A:$AD,MATCH(M1,Mapa_RA_CE!$1:$1,0),FALSE),""),"") | ... AC17: =IFERROR(IF(VLOOKUP($B17,Mapa_RA_CE!$A:$AD,MATCH(AC1,Mapa_RA_CE!$1:$1,0),FALSE)>0,$D17*VLOOKUP($B17,Mapa_RA_CE!$A:$AD,MATCH(AC1,Mapa_RA_CE!$1:$1,0),FALSE),""),"")
C18: =IFERROR(VLOOKUP($B18,Mapa_RA_CE!$A:$AD,2,FALSE),"") | F18: =IFERROR(IF(VLOOKUP($B18,Mapa_RA_CE!$A:$AD,MATCH(F1,Mapa_RA_CE!$1:$1,0),FALSE)>0,$D18*VLOOKUP($B18,Mapa_RA_CE!$A:$AD,MATCH(F1,Mapa_RA_CE!$1:$1,0),FALSE),""),"") | G18: =IFERROR(IF(VLOOKUP($B18,Mapa_RA_CE!$A:$AD,MATCH(G1,Mapa_RA_CE!$1:$1,0),FALSE)>0,$D18*VLOOKUP($B18,Mapa_RA_CE!$A:$AD,MATCH(G1,Mapa_RA_CE!$1:$1,0),FALSE),""),"") | H18: =IFERROR(IF(VLOOKUP($B18,Mapa_RA_CE!$A:$AD,MATCH(H1,Mapa_RA_CE!$1:$1,0),FALSE)>0,$D18*VLOOKUP($B18,Mapa_RA_CE!$A:$AD,MATCH(H1,Mapa_RA_CE!$1:$1,0),FALSE),""),"") | I18: =IFERROR(IF(VLOOKUP($B18,Mapa_RA_CE!$A:$AD,MATCH(I1,Mapa_RA_CE!$1:$1,0),FALSE)>0,$D18*VLOOKUP($B18,Mapa_RA_CE!$A:$AD,MATCH(I1,Mapa_RA_CE!$1:$1,0),FALSE),""),"") | J18: =IFERROR(IF(VLOOKUP($B18,Mapa_RA_CE!$A:$AD,MATCH(J1,Mapa_RA_CE!$1:$1,0),FALSE)>0,$D18*VLOOKUP($B18,Mapa_RA_CE!$A:$AD,MATCH(J1,Mapa_RA_CE!$1:$1,0),FALSE),""),"") | K18: =IFERROR(IF(VLOOKUP($B18,Mapa_RA_CE!$A:$AD,MATCH(K1,Mapa_RA_CE!$1:$1,0),FALSE)>0,$D18*VLOOKUP($B18,Mapa_RA_CE!$A:$AD,MATCH(K1,Mapa_RA_CE!$1:$1,0),FALSE),""),"") | L18: =IFERROR(IF(VLOOKUP($B18,Mapa_RA_CE!$A:$AD,MATCH(L1,Mapa_RA_CE!$1:$1,0),FALSE)>0,$D18*VLOOKUP($B18,Mapa_RA_CE!$A:$AD,MATCH(L1,Mapa_RA_CE!$1:$1,0),FALSE),""),"") | M18: =IFERROR(IF(VLOOKUP($B18,Mapa_RA_CE!$A:$AD,MATCH(M1,Mapa_RA_CE!$1:$1,0),FALSE)>0,$D18*VLOOKUP($B18,Mapa_RA_CE!$A:$AD,MATCH(M1,Mapa_RA_CE!$1:$1,0),FALSE),""),"") | ... AC18: =IFERROR(IF(VLOOKUP($B18,Mapa_RA_CE!$A:$AD,MATCH(AC1,Mapa_RA_CE!$1:$1,0),FALSE)>0,$D18*VLOOKUP($B18,Mapa_RA_CE!$A:$AD,MATCH(AC1,Mapa_RA_CE!$1:$1,0),FALSE),""),"")
C19: =IFERROR(VLOOKUP($B19,Mapa_RA_CE!$A:$AD,2,FALSE),"") | F19: =IFERROR(IF(VLOOKUP($B19,Mapa_RA_CE!$A:$AD,MATCH(F1,Mapa_RA_CE!$1:$1,0),FALSE)>0,$D19*VLOOKUP($B19,Mapa_RA_CE!$A:$AD,MATCH(F1,Mapa_RA_CE!$1:$1,0),FALSE),""),"") | G19: =IFERROR(IF(VLOOKUP($B19,Mapa_RA_CE!$A:$AD,MATCH(G1,Mapa_RA_CE!$1:$1,0),FALSE)>0,$D19*VLOOKUP($B19,Mapa_RA_CE!$A:$AD,MATCH(G1,Mapa_RA_CE!$1:$1,0),FALSE),""),"") | H19: =IFERROR(IF(VLOOKUP($B19,Mapa_RA_CE!$A:$AD,MATCH(H1,Mapa_RA_CE!$1:$1,0),FALSE)>0,$D19*VLOOKUP($B19,Mapa_RA_CE!$A:$AD,MATCH(H1,Mapa_RA_CE!$1:$1,0),FALSE),""),"") | I19: =IFERROR(IF(VLOOKUP($B19,Mapa_RA_CE!$A:$AD,MATCH(I1,Mapa_RA_CE!$1:$1,0),FALSE)>0,$D19*VLOOKUP($B19,Mapa_RA_CE!$A:$AD,MATCH(I1,Mapa_RA_CE!$1:$1,0),FALSE),""),"") | J19: =IFERROR(IF(VLOOKUP($B19,Mapa_RA_CE!$A:$AD,MATCH(J1,Mapa_RA_CE!$1:$1,0),FALSE)>0,$D19*VLOOKUP($B19,Mapa_RA_CE!$A:$AD,MATCH(J1,Mapa_RA_CE!$1:$1,0),FALSE),""),"") | K19: =IFERROR(IF(VLOOKUP($B19,Mapa_RA_CE!$A:$AD,MATCH(K1,Mapa_RA_CE!$1:$1,0),FALSE)>0,$D19*VLOOKUP($B19,Mapa_RA_CE!$A:$AD,MATCH(K1,Mapa_RA_CE!$1:$1,0),FALSE),""),"") | L19: =IFERROR(IF(VLOOKUP($B19,Mapa_RA_CE!$A:$AD,MATCH(L1,Mapa_RA_CE!$1:$1,0),FALSE)>0,$D19*VLOOKUP($B19,Mapa_RA_CE!$A:$AD,MATCH(L1,Mapa_RA_CE!$1:$1,0),FALSE),""),"") | M19: =IFERROR(IF(VLOOKUP($B19,Mapa_RA_CE!$A:$AD,MATCH(M1,Mapa_RA_CE!$1:$1,0),FALSE)>0,$D19*VLOOKUP($B19,Mapa_RA_CE!$A:$AD,MATCH(M1,Mapa_RA_CE!$1:$1,0),FALSE),""),"") | ... AC19: =IFERROR(IF(VLOOKUP($B19,Mapa_RA_CE!$A:$AD,MATCH(AC1,Mapa_RA_CE!$1:$1,0),FALSE)>0,$D19*VLOOKUP($B19,Mapa_RA_CE!$A:$AD,MATCH(AC1,Mapa_RA_CE!$1:$1,0),FALSE),""),"")
C20: =IFERROR(VLOOKUP($B20,Mapa_RA_CE!$A:$AD,2,FALSE),"") | F20: =IFERROR(IF(VLOOKUP($B20,Mapa_RA_CE!$A:$AD,MATCH(F1,Mapa_RA_CE!$1:$1,0),FALSE)>0,$D20*VLOOKUP($B20,Mapa_RA_CE!$A:$AD,MATCH(F1,Mapa_RA_CE!$1:$1,0),FALSE),""),"") | G20: =IFERROR(IF(VLOOKUP($B20,Mapa_RA_CE!$A:$AD,MATCH(G1,Mapa_RA_CE!$1:$1,0),FALSE)>0,$D20*VLOOKUP($B20,Mapa_RA_CE!$A:$AD,MATCH(G1,Mapa_RA_CE!$1:$1,0),FALSE),""),"") | H20: =IFERROR(IF(VLOOKUP($B20,Mapa_RA_CE!$A:$AD,MATCH(H1,Mapa_RA_CE!$1:$1,0),FALSE)>0,$D20*VLOOKUP($B20,Mapa_RA_CE!$A:$AD,MATCH(H1,Mapa_RA_CE!$1:$1,0),FALSE),""),"") | I20: =IFERROR(IF(VLOOKUP($B20,Mapa_RA_CE!$A:$AD,MATCH(I1,Mapa_RA_CE!$1:$1,0),FALSE)>0,$D20*VLOOKUP($B20,Mapa_RA_CE!$A:$AD,MATCH(I1,Mapa_RA_CE!$1:$1,0),FALSE),""),"") | J20: =IFERROR(IF(VLOOKUP($B20,Mapa_RA_CE!$A:$AD,MATCH(J1,Mapa_RA_CE!$1:$1,0),FALSE)>0,$D20*VLOOKUP($B20,Mapa_RA_CE!$A:$AD,MATCH(J1,Mapa_RA_CE!$1:$1,0),FALSE),""),"") | K20: =IFERROR(IF(VLOOKUP($B20,Mapa_RA_CE!$A:$AD,MATCH(K1,Mapa_RA_CE!$1:$1,0),FALSE)>0,$D20*VLOOKUP($B20,Mapa_RA_CE!$A:$AD,MATCH(K1,Mapa_RA_CE!$1:$1,0),FALSE),""),"") | L20: =IFERROR(IF(VLOOKUP($B20,Mapa_RA_CE!$A:$AD,MATCH(L1,Mapa_RA_CE!$1:$1,0),FALSE)>0,$D20*VLOOKUP($B20,Mapa_RA_CE!$A:$AD,MATCH(L1,Mapa_RA_CE!$1:$1,0),FALSE),""),"") | M20: =IFERROR(IF(VLOOKUP($B20,Mapa_RA_CE!$A:$AD,MATCH(M1,Mapa_RA_CE!$1:$1,0),FALSE)>0,$D20*VLOOKUP($B20,Mapa_RA_CE!$A:$AD,MATCH(M1,Mapa_RA_CE!$1:$1,0),FALSE),""),"") | ... AC20: =IFERROR(IF(VLOOKUP($B20,Mapa_RA_CE!$A:$AD,MATCH(AC1,Mapa_RA_CE!$1:$1,0),FALSE)>0,$D20*VLOOKUP($B20,Mapa_RA_CE!$A:$AD,MATCH(AC1,Mapa_RA_CE!$1:$1,0),FALSE),""),"")
C21: =IFERROR(VLOOKUP($B21,Mapa_RA_CE!$A:$AD,2,FALSE),"") | F21: =IFERROR(IF(VLOOKUP($B21,Mapa_RA_CE!$A:$AD,MATCH(F1,Mapa_RA_CE!$1:$1,0),FALSE)>0,$D21*VLOOKUP($B21,Mapa_RA_CE!$A:$AD,MATCH(F1,Mapa_RA_CE!$1:$1,0),FALSE),""),"") | G21: =IFERROR(IF(VLOOKUP($B21,Mapa_RA_CE!$A:$AD,MATCH(G1,Mapa_RA_CE!$1:$1,0),FALSE)>0,$D21*VLOOKUP($B21,Mapa_RA_CE!$A:$AD,MATCH(G1,Mapa_RA_CE!$1:$1,0),FALSE),""),"") | H21: =IFERROR(IF(VLOOKUP($B21,Mapa_RA_CE!$A:$AD,MATCH(H1,Mapa_RA_CE!$1:$1,0),FALSE)>0,$D21*VLOOKUP($B21,Mapa_RA_CE!$A:$AD,MATCH(H1,Mapa_RA_CE!$1:$1,0),FALSE),""),"") | I21: =IFERROR(IF(VLOOKUP($B21,Mapa_RA_CE!$A:$AD,MATCH(I1,Mapa_RA_CE!$1:$1,0),FALSE)>0,$D21*VLOOKUP($B21,Mapa_RA_CE!$A:$AD,MATCH(I1,Mapa_RA_CE!$1:$1,0),FALSE),""),"") | J21: =IFERROR(IF(VLOOKUP($B21,Mapa_RA_CE!$A:$AD,MATCH(J1,Mapa_RA_CE!$1:$1,0),FALSE)>0,$D21*VLOOKUP($B21,Mapa_RA_CE!$A:$AD,MATCH(J1,Mapa_RA_CE!$1:$1,0),FALSE),""),"") | K21: =IFERROR(IF(VLOOKUP($B21,Mapa_RA_CE!$A:$AD,MATCH(K1,Mapa_RA_CE!$1:$1,0),FALSE)>0,$D21*VLOOKUP($B21,Mapa_RA_CE!$A:$AD,MATCH(K1,Mapa_RA_CE!$1:$1,0),FALSE),""),"") | L21: =IFERROR(IF(VLOOKUP($B21,Mapa_RA_CE!$A:$AD,MATCH(L1,Mapa_RA_CE!$1:$1,0),FALSE)>0,$D21*VLOOKUP($B21,Mapa_RA_CE!$A:$AD,MATCH(L1,Mapa_RA_CE!$1:$1,0),FALSE),""),"") | M21: =IFERROR(IF(VLOOKUP($B21,Mapa_RA_CE!$A:$AD,MATCH(M1,Mapa_RA_CE!$1:$1,0),FALSE)>0,$D21*VLOOKUP($B21,Mapa_RA_CE!$A:$AD,MATCH(M1,Mapa_RA_CE!$1:$1,0),FALSE),""),"") | ... AC21: =IFERROR(IF(VLOOKUP($B21,Mapa_RA_CE!$A:$AD,MATCH(AC1,Mapa_RA_CE!$1:$1,0),FALSE)>0,$D21*VLOOKUP($B21,Mapa_RA_CE!$A:$AD,MATCH(AC1,Mapa_RA_CE!$1:$1,0),FALSE),""),"")
C22: =IFERROR(VLOOKUP($B22,Mapa_RA_CE!$A:$AD,2,FALSE),"") | F22: =IFERROR(IF(VLOOKUP($B22,Mapa_RA_CE!$A:$AD,MATCH(F1,Mapa_RA_CE!$1:$1,0),FALSE)>0,$D22*VLOOKUP($B22,Mapa_RA_CE!$A:$AD,MATCH(F1,Mapa_RA_CE!$1:$1,0),FALSE),""),"") | G22: =IFERROR(IF(VLOOKUP($B22,Mapa_RA_CE!$A:$AD,MATCH(G1,Mapa_RA_CE!$1:$1,0),FALSE)>0,$D22*VLOOKUP($B22,Mapa_RA_CE!$A:$AD,MATCH(G1,Mapa_RA_CE!$1:$1,0),FALSE),""),"") | H22: =IFERROR(IF(VLOOKUP($B22,Mapa_RA_CE!$A:$AD,MATCH(H1,Mapa_RA_CE!$1:$1,0),FALSE)>0,$D22*VLOOKUP($B22,Mapa_RA_CE!$A:$AD,MATCH(H1,Mapa_RA_CE!$1:$1,0),FALSE),""),"") | I22: =IFERROR(IF(VLOOKUP($B22,Mapa_RA_CE!$A:$AD,MATCH(I1,Mapa_RA_CE!$1:$1,0),FALSE)>0,$D22*VLOOKUP($B22,Mapa_RA_CE!$A:$AD,MATCH(I1,Mapa_RA_CE!$1:$1,0),FALSE),""),"") | J22: =IFERROR(IF(VLOOKUP($B22,Mapa_RA_CE!$A:$AD,MATCH(J1,Mapa_RA_CE!$1:$1,0),FALSE)>0,$D22*VLOOKUP($B22,Mapa_RA_CE!$A:$AD,MATCH(J1,Mapa_RA_CE!$1:$1,0),FALSE),""),"") | K22: =IFERROR(IF(VLOOKUP($B22,Mapa_RA_CE!$A:$AD,MATCH(K1,Mapa_RA_CE!$1:$1,0),FALSE)>0,$D22*VLOOKUP($B22,Mapa_RA_CE!$A:$AD,MATCH(K1,Mapa_RA_CE!$1:$1,0),FALSE),""),"") | L22: =IFERROR(IF(VLOOKUP($B22,Mapa_RA_CE!$A:$AD,MATCH(L1,Mapa_RA_CE!$1:$1,0),FALSE)>0,$D22*VLOOKUP($B22,Mapa_RA_CE!$A:$AD,MATCH(L1,Mapa_RA_CE!$1:$1,0),FALSE),""),"") | M22: =IFERROR(IF(VLOOKUP($B22,Mapa_RA_CE!$A:$AD,MATCH(M1,Mapa_RA_CE!$1:$1,0),FALSE)>0,$D22*VLOOKUP($B22,Mapa_RA_CE!$A:$AD,MATCH(M1,Mapa_RA_CE!$1:$1,0),FALSE),""),"") | ... AC22: =IFERROR(IF(VLOOKUP($B22,Mapa_RA_CE!$A:$AD,MATCH(AC1,Mapa_RA_CE!$1:$1,0),FALSE)>0,$D22*VLOOKUP($B22,Mapa_RA_CE!$A:$AD,MATCH(AC1,Mapa_RA_CE!$1:$1,0),FALSE),""),"")
C23: =IFERROR(VLOOKUP($B23,Mapa_RA_CE!$A:$AD,2,FALSE),"") | F23: =IFERROR(IF(VLOOKUP($B23,Mapa_RA_CE!$A:$AD,MATCH(F1,Mapa_RA_CE!$1:$1,0),FALSE)>0,$D23*VLOOKUP($B23,Mapa_RA_CE!$A:$AD,MATCH(F1,Mapa_RA_CE!$1:$1,0),FALSE),""),"") | G23: =IFERROR(IF(VLOOKUP($B23,Mapa_RA_CE!$A:$AD,MATCH(G1,Mapa_RA_CE!$1:$1,0),FALSE)>0,$D23*VLOOKUP($B23,Mapa_RA_CE!$A:$AD,MATCH(G1,Mapa_RA_CE!$1:$1,0),FALSE),""),"") | H23: =IFERROR(IF(VLOOKUP($B23,Mapa_RA_CE!$A:$AD,MATCH(H1,Mapa_RA_CE!$1:$1,0),FALSE)>0,$D23*VLOOKUP($B23,Mapa_RA_CE!$A:$AD,MATCH(H1,Mapa_RA_CE!$1:$1,0),FALSE),""),"") | I23: =IFERROR(IF(VLOOKUP($B23,Mapa_RA_CE!$A:$AD,MATCH(I1,Mapa_RA_CE!$1:$1,0),FALSE)>0,$D23*VLOOKUP($B23,Mapa_RA_CE!$A:$AD,MATCH(I1,Mapa_RA_CE!$1:$1,0),FALSE),""),"") | J23: =IFERROR(IF(VLOOKUP($B23,Mapa_RA_CE!$A:$AD,MATCH(J1,Mapa_RA_CE!$1:$1,0),FALSE)>0,$D23*VLOOKUP($B23,Mapa_RA_CE!$A:$AD,MATCH(J1,Mapa_RA_CE!$1:$1,0),FALSE),""),"") | K23: =IFERROR(IF(VLOOKUP($B23,Mapa_RA_CE!$A:$AD,MATCH(K1,Mapa_RA_CE!$1:$1,0),FALSE)>0,$D23*VLOOKUP($B23,Mapa_RA_CE!$A:$AD,MATCH(K1,Mapa_RA_CE!$1:$1,0),FALSE),""),"") | L23: =IFERROR(IF(VLOOKUP($B23,Mapa_RA_CE!$A:$AD,MATCH(L1,Mapa_RA_CE!$1:$1,0),FALSE)>0,$D23*VLOOKUP($B23,Mapa_RA_CE!$A:$AD,MATCH(L1,Mapa_RA_CE!$1:$1,0),FALSE),""),"") | M23: =IFERROR(IF(VLOOKUP($B23,Mapa_RA_CE!$A:$AD,MATCH(M1,Mapa_RA_CE!$1:$1,0),FALSE)>0,$D23*VLOOKUP($B23,Mapa_RA_CE!$A:$AD,MATCH(M1,Mapa_RA_CE!$1:$1,0),FALSE),""),"") | ... AC23: =IFERROR(IF(VLOOKUP($B23,Mapa_RA_CE!$A:$AD,MATCH(AC1,Mapa_RA_CE!$1:$1,0),FALSE)>0,$D23*VLOOKUP($B23,Mapa_RA_CE!$A:$AD,MATCH(AC1,Mapa_RA_CE!$1:$1,0),FALSE),""),"")
C24: =IFERROR(VLOOKUP($B24,Mapa_RA_CE!$A:$AD,2,FALSE),"") | F24: =IFERROR(IF(VLOOKUP($B24,Mapa_RA_CE!$A:$AD,MATCH(F1,Mapa_RA_CE!$1:$1,0),FALSE)>0,$D24*VLOOKUP($B24,Mapa_RA_CE!$A:$AD,MATCH(F1,Mapa_RA_CE!$1:$1,0),FALSE),""),"") | G24: =IFERROR(IF(VLOOKUP($B24,Mapa_RA_CE!$A:$AD,MATCH(G1,Mapa_RA_CE!$1:$1,0),FALSE)>0,$D24*VLOOKUP($B24,Mapa_RA_CE!$A:$AD,MATCH(G1,Mapa_RA_CE!$1:$1,0),FALSE),""),"") | H24: =IFERROR(IF(VLOOKUP($B24,Mapa_RA_CE!$A:$AD,MATCH(H1,Mapa_RA_CE!$1:$1,0),FALSE)>0,$D24*VLOOKUP($B24,Mapa_RA_CE!$A:$AD,MATCH(H1,Mapa_RA_CE!$1:$1,0),FALSE),""),"") | I24: =IFERROR(IF(VLOOKUP($B24,Mapa_RA_CE!$A:$AD,MATCH(I1,Mapa_RA_CE!$1:$1,0),FALSE)>0,$D24*VLOOKUP($B24,Mapa_RA_CE!$A:$AD,MATCH(I1,Mapa_RA_CE!$1:$1,0),FALSE),""),"") | J24: =IFERROR(IF(VLOOKUP($B24,Mapa_RA_CE!$A:$AD,MATCH(J1,Mapa_RA_CE!$1:$1,0),FALSE)>0,$D24*VLOOKUP($B24,Mapa_RA_CE!$A:$AD,MATCH(J1,Mapa_RA_CE!$1:$1,0),FALSE),""),"") | K24: =IFERROR(IF(VLOOKUP($B24,Mapa_RA_CE!$A:$AD,MATCH(K1,Mapa_RA_CE!$1:$1,0),FALSE)>0,$D24*VLOOKUP($B24,Mapa_RA_CE!$A:$AD,MATCH(K1,Mapa_RA_CE!$1:$1,0),FALSE),""),"") | L24: =IFERROR(IF(VLOOKUP($B24,Mapa_RA_CE!$A:$AD,MATCH(L1,Mapa_RA_CE!$1:$1,0),FALSE)>0,$D24*VLOOKUP($B24,Mapa_RA_CE!$A:$AD,MATCH(L1,Mapa_RA_CE!$1:$1,0),FALSE),""),"") | M24: =IFERROR(IF(VLOOKUP($B24,Mapa_RA_CE!$A:$AD,MATCH(M1,Mapa_RA_CE!$1:$1,0),FALSE)>0,$D24*VLOOKUP($B24,Mapa_RA_CE!$A:$AD,MATCH(M1,Mapa_RA_CE!$1:$1,0),FALSE),""),"") | ... AC24: =IFERROR(IF(VLOOKUP($B24,Mapa_RA_CE!$A:$AD,MATCH(AC1,Mapa_RA_CE!$1:$1,0),FALSE)>0,$D24*VLOOKUP($B24,Mapa_RA_CE!$A:$AD,MATCH(AC1,Mapa_RA_CE!$1:$1,0),FALSE),""),"")
C25: =IFERROR(VLOOKUP($B25,Mapa_RA_CE!$A:$AD,2,FALSE),"") | F25: =IFERROR(IF(VLOOKUP($B25,Mapa_RA_CE!$A:$AD,MATCH(F1,Mapa_RA_CE!$1:$1,0),FALSE)>0,$D25*VLOOKUP($B25,Mapa_RA_CE!$A:$AD,MATCH(F1,Mapa_RA_CE!$1:$1,0),FALSE),""),"") | G25: =IFERROR(IF(VLOOKUP($B25,Mapa_RA_CE!$A:$AD,MATCH(G1,Mapa_RA_CE!$1:$1,0),FALSE)>0,$D25*VLOOKUP($B25,Mapa_RA_CE!$A:$AD,MATCH(G1,Mapa_RA_CE!$1:$1,0),FALSE),""),"") | H25: =IFERROR(IF(VLOOKUP($B25,Mapa_RA_CE!$A:$AD,MATCH(H1,Mapa_RA_CE!$1:$1,0),FALSE)>0,$D25*VLOOKUP($B25,Mapa_RA_CE!$A:$AD,MATCH(H1,Mapa_RA_CE!$1:$1,0),FALSE),""),"") | I25: =IFERROR(IF(VLOOKUP($B25,Mapa_RA_CE!$A:$AD,MATCH(I1,Mapa_RA_CE!$1:$1,0),FALSE)>0,$D25*VLOOKUP($B25,Mapa_RA_CE!$A:$AD,MATCH(I1,Mapa_RA_CE!$1:$1,0),FALSE),""),"") | J25: =IFERROR(IF(VLOOKUP($B25,Mapa_RA_CE!$A:$AD,MATCH(J1,Mapa_RA_CE!$1:$1,0),FALSE)>0,$D25*VLOOKUP($B25,Mapa_RA_CE!$A:$AD,MATCH(J1,Mapa_RA_CE!$1:$1,0),FALSE),""),"") | K25: =IFERROR(IF(VLOOKUP($B25,Mapa_RA_CE!$A:$AD,MATCH(K1,Mapa_RA_CE!$1:$1,0),FALSE)>0,$D25*VLOOKUP($B25,Mapa_RA_CE!$A:$AD,MATCH(K1,Mapa_RA_CE!$1:$1,0),FALSE),""),"") | L25: =IFERROR(IF(VLOOKUP($B25,Mapa_RA_CE!$A:$AD,MATCH(L1,Mapa_RA_CE!$1:$1,0),FALSE)>0,$D25*VLOOKUP($B25,Mapa_RA_CE!$A:$AD,MATCH(L1,Mapa_RA_CE!$1:$1,0),FALSE),""),"") | M25: =IFERROR(IF(VLOOKUP($B25,Mapa_RA_CE!$A:$AD,MATCH(M1,Mapa_RA_CE!$1:$1,0),FALSE)>0,$D25*VLOOKUP($B25,Mapa_RA_CE!$A:$AD,MATCH(M1,Mapa_RA_CE!$1:$1,0),FALSE),""),"") | ... AC25: =IFERROR(IF(VLOOKUP($B25,Mapa_RA_CE!$A:$AD,MATCH(AC1,Mapa_RA_CE!$1:$1,0),FALSE)>0,$D25*VLOOKUP($B25,Mapa_RA_CE!$A:$AD,MATCH(AC1,Mapa_RA_CE!$1:$1,0),FALSE),""),"")
C26: =IFERROR(VLOOKUP($B26,Mapa_RA_CE!$A:$AD,2,FALSE),"") | F26: =IFERROR(IF(VLOOKUP($B26,Mapa_RA_CE!$A:$AD,MATCH(F1,Mapa_RA_CE!$1:$1,0),FALSE)>0,$D26*VLOOKUP($B26,Mapa_RA_CE!$A:$AD,MATCH(F1,Mapa_RA_CE!$1:$1,0),FALSE),""),"") | G26: =IFERROR(IF(VLOOKUP($B26,Mapa_RA_CE!$A:$AD,MATCH(G1,Mapa_RA_CE!$1:$1,0),FALSE)>0,$D26*VLOOKUP($B26,Mapa_RA_CE!$A:$AD,MATCH(G1,Mapa_RA_CE!$1:$1,0),FALSE),""),"") | H26: =IFERROR(IF(VLOOKUP($B26,Mapa_RA_CE!$A:$AD,MATCH(H1,Mapa_RA_CE!$1:$1,0),FALSE)>0,$D26*VLOOKUP($B26,Mapa_RA_CE!$A:$AD,MATCH(H1,Mapa_RA_CE!$1:$1,0),FALSE),""),"") | I26: =IFERROR(IF(VLOOKUP($B26,Mapa_RA_CE!$A:$AD,MATCH(I1,Mapa_RA_CE!$1:$1,0),FALSE)>0,$D26*VLOOKUP($B26,Mapa_RA_CE!$A:$AD,MATCH(I1,Mapa_RA_CE!$1:$1,0),FALSE),""),"") | J26: =IFERROR(IF(VLOOKUP($B26,Mapa_RA_CE!$A:$AD,MATCH(J1,Mapa_RA_CE!$1:$1,0),FALSE)>0,$D26*VLOOKUP($B26,Mapa_RA_CE!$A:$AD,MATCH(J1,Mapa_RA_CE!$1:$1,0),FALSE),""),"") | K26: =IFERROR(IF(VLOOKUP($B26,Mapa_RA_CE!$A:$AD,MATCH(K1,Mapa_RA_CE!$1:$1,0),FALSE)>0,$D26*VLOOKUP($B26,Mapa_RA_CE!$A:$AD,MATCH(K1,Mapa_RA_CE!$1:$1,0),FALSE),""),"") | L26: =IFERROR(IF(VLOOKUP($B26,Mapa_RA_CE!$A:$AD,MATCH(L1,Mapa_RA_CE!$1:$1,0),FALSE)>0,$D26*VLOOKUP($B26,Mapa_RA_CE!$A:$AD,MATCH(L1,Mapa_RA_CE!$1:$1,0),FALSE),""),"") | M26: =IFERROR(IF(VLOOKUP($B26,Mapa_RA_CE!$A:$AD,MATCH(M1,Mapa_RA_CE!$1:$1,0),FALSE)>0,$D26*VLOOKUP($B26,Mapa_RA_CE!$A:$AD,MATCH(M1,Mapa_RA_CE!$1:$1,0),FALSE),""),"") | ... AC26: =IFERROR(IF(VLOOKUP($B26,Mapa_RA_CE!$A:$AD,MATCH(AC1,Mapa_RA_CE!$1:$1,0),FALSE)>0,$D26*VLOOKUP($B26,Mapa_RA_CE!$A:$AD,MATCH(AC1,Mapa_RA_CE!$1:$1,0),FALSE),""),"")
C27: =IFERROR(VLOOKUP($B27,Mapa_RA_CE!$A:$AD,2,FALSE),"") | F27: =IFERROR(IF(VLOOKUP($B27,Mapa_RA_CE!$A:$AD,MATCH(F1,Mapa_RA_CE!$1:$1,0),FALSE)>0,$D27*VLOOKUP($B27,Mapa_RA_CE!$A:$AD,MATCH(F1,Mapa_RA_CE!$1:$1,0),FALSE),""),"") | G27: =IFERROR(IF(VLOOKUP($B27,Mapa_RA_CE!$A:$AD,MATCH(G1,Mapa_RA_CE!$1:$1,0),FALSE)>0,$D27*VLOOKUP($B27,Mapa_RA_CE!$A:$AD,MATCH(G1,Mapa_RA_CE!$1:$1,0),FALSE),""),"") | H27: =IFERROR(IF(VLOOKUP($B27,Mapa_RA_CE!$A:$AD,MATCH(H1,Mapa_RA_CE!$1:$1,0),FALSE)>0,$D27*VLOOKUP($B27,Mapa_RA_CE!$A:$AD,MATCH(H1,Mapa_RA_CE!$1:$1,0),FALSE),""),"") | I27: =IFERROR(IF(VLOOKUP($B27,Mapa_RA_CE!$A:$AD,MATCH(I1,Mapa_RA_CE!$1:$1,0),FALSE)>0,$D27*VLOOKUP($B27,Mapa_RA_CE!$A:$AD,MATCH(I1,Mapa_RA_CE!$1:$1,0),FALSE),""),"") | J27: =IFERROR(IF(VLOOKUP($B27,Mapa_RA_CE!$A:$AD,MATCH(J1,Mapa_RA_CE!$1:$1,0),FALSE)>0,$D27*VLOOKUP($B27,Mapa_RA_CE!$A:$AD,MATCH(J1,Mapa_RA_CE!$1:$1,0),FALSE),""),"") | K27: =IFERROR(IF(VLOOKUP($B27,Mapa_RA_CE!$A:$AD,MATCH(K1,Mapa_RA_CE!$1:$1,0),FALSE)>0,$D27*VLOOKUP($B27,Mapa_RA_CE!$A:$AD,MATCH(K1,Mapa_RA_CE!$1:$1,0),FALSE),""),"") | L27: =IFERROR(IF(VLOOKUP($B27,Mapa_RA_CE!$A:$AD,MATCH(L1,Mapa_RA_CE!$1:$1,0),FALSE)>0,$D27*VLOOKUP($B27,Mapa_RA_CE!$A:$AD,MATCH(L1,Mapa_RA_CE!$1:$1,0),FALSE),""),"") | M27: =IFERROR(IF(VLOOKUP($B27,Mapa_RA_CE!$A:$AD,MATCH(M1,Mapa_RA_CE!$1:$1,0),FALSE)>0,$D27*VLOOKUP($B27,Mapa_RA_CE!$A:$AD,MATCH(M1,Mapa_RA_CE!$1:$1,0),FALSE),""),"") | ... AC27: =IFERROR(IF(VLOOKUP($B27,Mapa_RA_CE!$A:$AD,MATCH(AC1,Mapa_RA_CE!$1:$1,0),FALSE)>0,$D27*VLOOKUP($B27,Mapa_RA_CE!$A:$AD,MATCH(AC1,Mapa_RA_CE!$1:$1,0),FALSE),""),"")
C28: =IFERROR(VLOOKUP($B28,Mapa_RA_CE!$A:$AD,2,FALSE),"") | F28: =IFERROR(IF(VLOOKUP($B28,Mapa_RA_CE!$A:$AD,MATCH(F1,Mapa_RA_CE!$1:$1,0),FALSE)>0,$D28*VLOOKUP($B28,Mapa_RA_CE!$A:$AD,MATCH(F1,Mapa_RA_CE!$1:$1,0),FALSE),""),"") | G28: =IFERROR(IF(VLOOKUP($B28,Mapa_RA_CE!$A:$AD,MATCH(G1,Mapa_RA_CE!$1:$1,0),FALSE)>0,$D28*VLOOKUP($B28,Mapa_RA_CE!$A:$AD,MATCH(G1,Mapa_RA_CE!$1:$1,0),FALSE),""),"") | H28: =IFERROR(IF(VLOOKUP($B28,Mapa_RA_CE!$A:$AD,MATCH(H1,Mapa_RA_CE!$1:$1,0),FALSE)>0,$D28*VLOOKUP($B28,Mapa_RA_CE!$A:$AD,MATCH(H1,Mapa_RA_CE!$1:$1,0),FALSE),""),"") | I28: =IFERROR(IF(VLOOKUP($B28,Mapa_RA_CE!$A:$AD,MATCH(I1,Mapa_RA_CE!$1:$1,0),FALSE)>0,$D28*VLOOKUP($B28,Mapa_RA_CE!$A:$AD,MATCH(I1,Mapa_RA_CE!$1:$1,0),FALSE),""),"") | J28: =IFERROR(IF(VLOOKUP($B28,Mapa_RA_CE!$A:$AD,MATCH(J1,Mapa_RA_CE!$1:$1,0),FALSE)>0,$D28*VLOOKUP($B28,Mapa_RA_CE!$A:$AD,MATCH(J1,Mapa_RA_CE!$1:$1,0),FALSE),""),"") | K28: =IFERROR(IF(VLOOKUP($B28,Mapa_RA_CE!$A:$AD,MATCH(K1,Mapa_RA_CE!$1:$1,0),FALSE)>0,$D28*VLOOKUP($B28,Mapa_RA_CE!$A:$AD,MATCH(K1,Mapa_RA_CE!$1:$1,0),FALSE),""),"") | L28: =IFERROR(IF(VLOOKUP($B28,Mapa_RA_CE!$A:$AD,MATCH(L1,Mapa_RA_CE!$1:$1,0),FALSE)>0,$D28*VLOOKUP($B28,Mapa_RA_CE!$A:$AD,MATCH(L1,Mapa_RA_CE!$1:$1,0),FALSE),""),"") | M28: =IFERROR(IF(VLOOKUP($B28,Mapa_RA_CE!$A:$AD,MATCH(M1,Mapa_RA_CE!$1:$1,0),FALSE)>0,$D28*VLOOKUP($B28,Mapa_RA_CE!$A:$AD,MATCH(M1,Mapa_RA_CE!$1:$1,0),FALSE),""),"") | ... AC28: =IFERROR(IF(VLOOKUP($B28,Mapa_RA_CE!$A:$AD,MATCH(AC1,Mapa_RA_CE!$1:$1,0),FALSE)>0,$D28*VLOOKUP($B28,Mapa_RA_CE!$A:$AD,MATCH(AC1,Mapa_RA_CE!$1:$1,0),FALSE),""),"")
C29: =IFERROR(VLOOKUP($B29,Mapa_RA_CE!$A:$AD,2,FALSE),"") | F29: =IFERROR(IF(VLOOKUP($B29,Mapa_RA_CE!$A:$AD,MATCH(F1,Mapa_RA_CE!$1:$1,0),FALSE)>0,$D29*VLOOKUP($B29,Mapa_RA_CE!$A:$AD,MATCH(F1,Mapa_RA_CE!$1:$1,0),FALSE),""),"") | G29: =IFERROR(IF(VLOOKUP($B29,Mapa_RA_CE!$A:$AD,MATCH(G1,Mapa_RA_CE!$1:$1,0),FALSE)>0,$D29*VLOOKUP($B29,Mapa_RA_CE!$A:$AD,MATCH(G1,Mapa_RA_CE!$1:$1,0),FALSE),""),"") | H29: =IFERROR(IF(VLOOKUP($B29,Mapa_RA_CE!$A:$AD,MATCH(H1,Mapa_RA_CE!$1:$1,0),FALSE)>0,$D29*VLOOKUP($B29,Mapa_RA_CE!$A:$AD,MATCH(H1,Mapa_RA_CE!$1:$1,0),FALSE),""),"") | I29: =IFERROR(IF(VLOOKUP($B29,Mapa_RA_CE!$A:$AD,MATCH(I1,Mapa_RA_CE!$1:$1,0),FALSE)>0,$D29*VLOOKUP($B29,Mapa_RA_CE!$A:$AD,MATCH(I1,Mapa_RA_CE!$1:$1,0),FALSE),""),"") | J29: =IFERROR(IF(VLOOKUP($B29,Mapa_RA_CE!$A:$AD,MATCH(J1,Mapa_RA_CE!$1:$1,0),FALSE)>0,$D29*VLOOKUP($B29,Mapa_RA_CE!$A:$AD,MATCH(J1,Mapa_RA_CE!$1:$1,0),FALSE),""),"") | K29: =IFERROR(IF(VLOOKUP($B29,Mapa_RA_CE!$A:$AD,MATCH(K1,Mapa_RA_CE!$1:$1,0),FALSE)>0,$D29*VLOOKUP($B29,Mapa_RA_CE!$A:$AD,MATCH(K1,Mapa_RA_CE!$1:$1,0),FALSE),""),"") | L29: =IFERROR(IF(VLOOKUP($B29,Mapa_RA_CE!$A:$AD,MATCH(L1,Mapa_RA_CE!$1:$1,0),FALSE)>0,$D29*VLOOKUP($B29,Mapa_RA_CE!$A:$AD,MATCH(L1,Mapa_RA_CE!$1:$1,0),FALSE),""),"") | M29: =IFERROR(IF(VLOOKUP($B29,Mapa_RA_CE!$A:$AD,MATCH(M1,Mapa_RA_CE!$1:$1,0),FALSE)>0,$D29*VLOOKUP($B29,Mapa_RA_CE!$A:$AD,MATCH(M1,Mapa_RA_CE!$1:$1,0),FALSE),""),"") | ... AC29: =IFERROR(IF(VLOOKUP($B29,Mapa_RA_CE!$A:$AD,MATCH(AC1,Mapa_RA_CE!$1:$1,0),FALSE)>0,$D29*VLOOKUP($B29,Mapa_RA_CE!$A:$AD,MATCH(AC1,Mapa_RA_CE!$1:$1,0),FALSE),""),"")
C30: =IFERROR(VLOOKUP($B30,Mapa_RA_CE!$A:$AD,2,FALSE),"") | F30: =IFERROR(IF(VLOOKUP($B30,Mapa_RA_CE!$A:$AD,MATCH(F1,Mapa_RA_CE!$1:$1,0),FALSE)>0,$D30*VLOOKUP($B30,Mapa_RA_CE!$A:$AD,MATCH(F1,Mapa_RA_CE!$1:$1,0),FALSE),""),"") | G30: =IFERROR(IF(VLOOKUP($B30,Mapa_RA_CE!$A:$AD,MATCH(G1,Mapa_RA_CE!$1:$1,0),FALSE)>0,$D30*VLOOKUP($B30,Mapa_RA_CE!$A:$AD,MATCH(G1,Mapa_RA_CE!$1:$1,0),FALSE),""),"") | H30: =IFERROR(IF(VLOOKUP($B30,Mapa_RA_CE!$A:$AD,MATCH(H1,Mapa_RA_CE!$1:$1,0),FALSE)>0,$D30*VLOOKUP($B30,Mapa_RA_CE!$A:$AD,MATCH(H1,Mapa_RA_CE!$1:$1,0),FALSE),""),"") | I30: =IFERROR(IF(VLOOKUP($B30,Mapa_RA_CE!$A:$AD,MATCH(I1,Mapa_RA_CE!$1:$1,0),FALSE)>0,$D30*VLOOKUP($B30,Mapa_RA_CE!$A:$AD,MATCH(I1,Mapa_RA_CE!$1:$1,0),FALSE),""),"") | J30: =IFERROR(IF(VLOOKUP($B30,Mapa_RA_CE!$A:$AD,MATCH(J1,Mapa_RA_CE!$1:$1,0),FALSE)>0,$D30*VLOOKUP($B30,Mapa_RA_CE!$A:$AD,MATCH(J1,Mapa_RA_CE!$1:$1,0),FALSE),""),"") | K30: =IFERROR(IF(VLOOKUP($B30,Mapa_RA_CE!$A:$AD,MATCH(K1,Mapa_RA_CE!$1:$1,0),FALSE)>0,$D30*VLOOKUP($B30,Mapa_RA_CE!$A:$AD,MATCH(K1,Mapa_RA_CE!$1:$1,0),FALSE),""),"") | L30: =IFERROR(IF(VLOOKUP($B30,Mapa_RA_CE!$A:$AD,MATCH(L1,Mapa_RA_CE!$1:$1,0),FALSE)>0,$D30*VLOOKUP($B30,Mapa_RA_CE!$A:$AD,MATCH(L1,Mapa_RA_CE!$1:$1,0),FALSE),""),"") | M30: =IFERROR(IF(VLOOKUP($B30,Mapa_RA_CE!$A:$AD,MATCH(M1,Mapa_RA_CE!$1:$1,0),FALSE)>0,$D30*VLOOKUP($B30,Mapa_RA_CE!$A:$AD,MATCH(M1,Mapa_RA_CE!$1:$1,0),FALSE),""),"") | ... AC30: =IFERROR(IF(VLOOKUP($B30,Mapa_RA_CE!$A:$AD,MATCH(AC1,Mapa_RA_CE!$1:$1,0),FALSE)>0,$D30*VLOOKUP($B30,Mapa_RA_CE!$A:$AD,MATCH(AC1,Mapa_RA_CE!$1:$1,0),FALSE),""),"")
C31: =IFERROR(VLOOKUP($B31,Mapa_RA_CE!$A:$AD,2,FALSE),"") | F31: =IFERROR(IF(VLOOKUP($B31,Mapa_RA_CE!$A:$AD,MATCH(F1,Mapa_RA_CE!$1:$1,0),FALSE)>0,$D31*VLOOKUP($B31,Mapa_RA_CE!$A:$AD,MATCH(F1,Mapa_RA_CE!$1:$1,0),FALSE),""),"") | G31: =IFERROR(IF(VLOOKUP($B31,Mapa_RA_CE!$A:$AD,MATCH(G1,Mapa_RA_CE!$1:$1,0),FALSE)>0,$D31*VLOOKUP($B31,Mapa_RA_CE!$A:$AD,MATCH(G1,Mapa_RA_CE!$1:$1,0),FALSE),""),"") | H31: =IFERROR(IF(VLOOKUP($B31,Mapa_RA_CE!$A:$AD,MATCH(H1,Mapa_RA_CE!$1:$1,0),FALSE)>0,$D31*VLOOKUP($B31,Mapa_RA_CE!$A:$AD,MATCH(H1,Mapa_RA_CE!$1:$1,0),FALSE),""),"") | I31: =IFERROR(IF(VLOOKUP($B31,Mapa_RA_CE!$A:$AD,MATCH(I1,Mapa_RA_CE!$1:$1,0),FALSE)>0,$D31*VLOOKUP($B31,Mapa_RA_CE!$A:$AD,MATCH(I1,Mapa_RA_CE!$1:$1,0),FALSE),""),"") | J31: =IFERROR(IF(VLOOKUP($B31,Mapa_RA_CE!$A:$AD,MATCH(J1,Mapa_RA_CE!$1:$1,0),FALSE)>0,$D31*VLOOKUP($B31,Mapa_RA_CE!$A:$AD,MATCH(J1,Mapa_RA_CE!$1:$1,0),FALSE),""),"") | K31: =IFERROR(IF(VLOOKUP($B31,Mapa_RA_CE!$A:$AD,MATCH(K1,Mapa_RA_CE!$1:$1,0),FALSE)>0,$D31*VLOOKUP($B31,Mapa_RA_CE!$A:$AD,MATCH(K1,Mapa_RA_CE!$1:$1,0),FALSE),""),"") | L31: =IFERROR(IF(VLOOKUP($B31,Mapa_RA_CE!$A:$AD,MATCH(L1,Mapa_RA_CE!$1:$1,0),FALSE)>0,$D31*VLOOKUP($B31,Mapa_RA_CE!$A:$AD,MATCH(L1,Mapa_RA_CE!$1:$1,0),FALSE),""),"") | M31: =IFERROR(IF(VLOOKUP($B31,Mapa_RA_CE!$A:$AD,MATCH(M1,Mapa_RA_CE!$1:$1,0),FALSE)>0,$D31*VLOOKUP($B31,Mapa_RA_CE!$A:$AD,MATCH(M1,Mapa_RA_CE!$1:$1,0),FALSE),""),"") | ... AC31: =IFERROR(IF(VLOOKUP($B31,Mapa_RA_CE!$A:$AD,MATCH(AC1,Mapa_RA_CE!$1:$1,0),FALSE)>0,$D31*VLOOKUP($B31,Mapa_RA_CE!$A:$AD,MATCH(AC1,Mapa_RA_CE!$1:$1,0),FALSE),""),"")
C32: =IFERROR(VLOOKUP($B32,Mapa_RA_CE!$A:$AD,2,FALSE),"") | F32: =IFERROR(IF(VLOOKUP($B32,Mapa_RA_CE!$A:$AD,MATCH(F1,Mapa_RA_CE!$1:$1,0),FALSE)>0,$D32*VLOOKUP($B32,Mapa_RA_CE!$A:$AD,MATCH(F1,Mapa_RA_CE!$1:$1,0),FALSE),""),"") | G32: =IFERROR(IF(VLOOKUP($B32,Mapa_RA_CE!$A:$AD,MATCH(G1,Mapa_RA_CE!$1:$1,0),FALSE)>0,$D32*VLOOKUP($B32,Mapa_RA_CE!$A:$AD,MATCH(G1,Mapa_RA_CE!$1:$1,0),FALSE),""),"") | H32: =IFERROR(IF(VLOOKUP($B32,Mapa_RA_CE!$A:$AD,MATCH(H1,Mapa_RA_CE!$1:$1,0),FALSE)>0,$D32*VLOOKUP($B32,Mapa_RA_CE!$A:$AD,MATCH(H1,Mapa_RA_CE!$1:$1,0),FALSE),""),"") | I32: =IFERROR(IF(VLOOKUP($B32,Mapa_RA_CE!$A:$AD,MATCH(I1,Mapa_RA_CE!$1:$1,0),FALSE)>0,$D32*VLOOKUP($B32,Mapa_RA_CE!$A:$AD,MATCH(I1,Mapa_RA_CE!$1:$1,0),FALSE),""),"") | J32: =IFERROR(IF(VLOOKUP($B32,Mapa_RA_CE!$A:$AD,MATCH(J1,Mapa_RA_CE!$1:$1,0),FALSE)>0,$D32*VLOOKUP($B32,Mapa_RA_CE!$A:$AD,MATCH(J1,Mapa_RA_CE!$1:$1,0),FALSE),""),"") | K32: =IFERROR(IF(VLOOKUP($B32,Mapa_RA_CE!$A:$AD,MATCH(K1,Mapa_RA_CE!$1:$1,0),FALSE)>0,$D32*VLOOKUP($B32,Mapa_RA_CE!$A:$AD,MATCH(K1,Mapa_RA_CE!$1:$1,0),FALSE),""),"") | L32: =IFERROR(IF(VLOOKUP($B32,Mapa_RA_CE!$A:$AD,MATCH(L1,Mapa_RA_CE!$1:$1,0),FALSE)>0,$D32*VLOOKUP($B32,Mapa_RA_CE!$A:$AD,MATCH(L1,Mapa_RA_CE!$1:$1,0),FALSE),""),"") | M32: =IFERROR(IF(VLOOKUP($B32,Mapa_RA_CE!$A:$AD,MATCH(M1,Mapa_RA_CE!$1:$1,0),FALSE)>0,$D32*VLOOKUP($B32,Mapa_RA_CE!$A:$AD,MATCH(M1,Mapa_RA_CE!$1:$1,0),FALSE),""),"") | ... AC32: =IFERROR(IF(VLOOKUP($B32,Mapa_RA_CE!$A:$AD,MATCH(AC1,Mapa_RA_CE!$1:$1,0),FALSE)>0,$D32*VLOOKUP($B32,Mapa_RA_CE!$A:$AD,MATCH(AC1,Mapa_RA_CE!$1:$1,0),FALSE),""),"")
C33: =IFERROR(VLOOKUP($B33,Mapa_RA_CE!$A:$AD,2,FALSE),"") | F33: =IFERROR(IF(VLOOKUP($B33,Mapa_RA_CE!$A:$AD,MATCH(F1,Mapa_RA_CE!$1:$1,0),FALSE)>0,$D33*VLOOKUP($B33,Mapa_RA_CE!$A:$AD,MATCH(F1,Mapa_RA_CE!$1:$1,0),FALSE),""),"") | G33: =IFERROR(IF(VLOOKUP($B33,Mapa_RA_CE!$A:$AD,MATCH(G1,Mapa_RA_CE!$1:$1,0),FALSE)>0,$D33*VLOOKUP($B33,Mapa_RA_CE!$A:$AD,MATCH(G1,Mapa_RA_CE!$1:$1,0),FALSE),""),"") | H33: =IFERROR(IF(VLOOKUP($B33,Mapa_RA_CE!$A:$AD,MATCH(H1,Mapa_RA_CE!$1:$1,0),FALSE)>0,$D33*VLOOKUP($B33,Mapa_RA_CE!$A:$AD,MATCH(H1,Mapa_RA_CE!$1:$1,0),FALSE),""),"") | I33: =IFERROR(IF(VLOOKUP($B33,Mapa_RA_CE!$A:$AD,MATCH(I1,Mapa_RA_CE!$1:$1,0),FALSE)>0,$D33*VLOOKUP($B33,Mapa_RA_CE!$A:$AD,MATCH(I1,Mapa_RA_CE!$1:$1,0),FALSE),""),"") | J33: =IFERROR(IF(VLOOKUP($B33,Mapa_RA_CE!$A:$AD,MATCH(J1,Mapa_RA_CE!$1:$1,0),FALSE)>0,$D33*VLOOKUP($B33,Mapa_RA_CE!$A:$AD,MATCH(J1,Mapa_RA_CE!$1:$1,0),FALSE),""),"") | K33: =IFERROR(IF(VLOOKUP($B33,Mapa_RA_CE!$A:$AD,MATCH(K1,Mapa_RA_CE!$1:$1,0),FALSE)>0,$D33*VLOOKUP($B33,Mapa_RA_CE!$A:$AD,MATCH(K1,Mapa_RA_CE!$1:$1,0),FALSE),""),"") | L33: =IFERROR(IF(VLOOKUP($B33,Mapa_RA_CE!$A:$AD,MATCH(L1,Mapa_RA_CE!$1:$1,0),FALSE)>0,$D33*VLOOKUP($B33,Mapa_RA_CE!$A:$AD,MATCH(L1,Mapa_RA_CE!$1:$1,0),FALSE),""),"") | M33: =IFERROR(IF(VLOOKUP($B33,Mapa_RA_CE!$A:$AD,MATCH(M1,Mapa_RA_CE!$1:$1,0),FALSE)>0,$D33*VLOOKUP($B33,Mapa_RA_CE!$A:$AD,MATCH(M1,Mapa_RA_CE!$1:$1,0),FALSE),""),"") | ... AC33: =IFERROR(IF(VLOOKUP($B33,Mapa_RA_CE!$A:$AD,MATCH(AC1,Mapa_RA_CE!$1:$1,0),FALSE)>0,$D33*VLOOKUP($B33,Mapa_RA_CE!$A:$AD,MATCH(AC1,Mapa_RA_CE!$1:$1,0),FALSE),""),"")
C34: =IFERROR(VLOOKUP($B34,Mapa_RA_CE!$A:$AD,2,FALSE),"") | F34: =IFERROR(IF(VLOOKUP($B34,Mapa_RA_CE!$A:$AD,MATCH(F1,Mapa_RA_CE!$1:$1,0),FALSE)>0,$D34*VLOOKUP($B34,Mapa_RA_CE!$A:$AD,MATCH(F1,Mapa_RA_CE!$1:$1,0),FALSE),""),"") | G34: =IFERROR(IF(VLOOKUP($B34,Mapa_RA_CE!$A:$AD,MATCH(G1,Mapa_RA_CE!$1:$1,0),FALSE)>0,$D34*VLOOKUP($B34,Mapa_RA_CE!$A:$AD,MATCH(G1,Mapa_RA_CE!$1:$1,0),FALSE),""),"") | H34: =IFERROR(IF(VLOOKUP($B34,Mapa_RA_CE!$A:$AD,MATCH(H1,Mapa_RA_CE!$1:$1,0),FALSE)>0,$D34*VLOOKUP($B34,Mapa_RA_CE!$A:$AD,MATCH(H1,Mapa_RA_CE!$1:$1,0),FALSE),""),"") | I34: =IFERROR(IF(VLOOKUP($B34,Mapa_RA_CE!$A:$AD,MATCH(I1,Mapa_RA_CE!$1:$1,0),FALSE)>0,$D34*VLOOKUP($B34,Mapa_RA_CE!$A:$AD,MATCH(I1,Mapa_RA_CE!$1:$1,0),FALSE),""),"") | J34: =IFERROR(IF(VLOOKUP($B34,Mapa_RA_CE!$A:$AD,MATCH(J1,Mapa_RA_CE!$1:$1,0),FALSE)>0,$D34*VLOOKUP($B34,Mapa_RA_CE!$A:$AD,MATCH(J1,Mapa_RA_CE!$1:$1,0),FALSE),""),"") | K34: =IFERROR(IF(VLOOKUP($B34,Mapa_RA_CE!$A:$AD,MATCH(K1,Mapa_RA_CE!$1:$1,0),FALSE)>0,$D34*VLOOKUP($B34,Mapa_RA_CE!$A:$AD,MATCH(K1,Mapa_RA_CE!$1:$1,0),FALSE),""),"") | L34: =IFERROR(IF(VLOOKUP($B34,Mapa_RA_CE!$A:$AD,MATCH(L1,Mapa_RA_CE!$1:$1,0),FALSE)>0,$D34*VLOOKUP($B34,Mapa_RA_CE!$A:$AD,MATCH(L1,Mapa_RA_CE!$1:$1,0),FALSE),""),"") | M34: =IFERROR(IF(VLOOKUP($B34,Mapa_RA_CE!$A:$AD,MATCH(M1,Mapa_RA_CE!$1:$1,0),FALSE)>0,$D34*VLOOKUP($B34,Mapa_RA_CE!$A:$AD,MATCH(M1,Mapa_RA_CE!$1:$1,0),FALSE),""),"") | ... AC34: =IFERROR(IF(VLOOKUP($B34,Mapa_RA_CE!$A:$AD,MATCH(AC1,Mapa_RA_CE!$1:$1,0),FALSE)>0,$D34*VLOOKUP($B34,Mapa_RA_CE!$A:$AD,MATCH(AC1,Mapa_RA_CE!$1:$1,0),FALSE),""),"")
C35: =IFERROR(VLOOKUP($B35,Mapa_RA_CE!$A:$AD,2,FALSE),"") | F35: =IFERROR(IF(VLOOKUP($B35,Mapa_RA_CE!$A:$AD,MATCH(F1,Mapa_RA_CE!$1:$1,0),FALSE)>0,$D35*VLOOKUP($B35,Mapa_RA_CE!$A:$AD,MATCH(F1,Mapa_RA_CE!$1:$1,0),FALSE),""),"") | G35: =IFERROR(IF(VLOOKUP($B35,Mapa_RA_CE!$A:$AD,MATCH(G1,Mapa_RA_CE!$1:$1,0),FALSE)>0,$D35*VLOOKUP($B35,Mapa_RA_CE!$A:$AD,MATCH(G1,Mapa_RA_CE!$1:$1,0),FALSE),""),"") | H35: =IFERROR(IF(VLOOKUP($B35,Mapa_RA_CE!$A:$AD,MATCH(H1,Mapa_RA_CE!$1:$1,0),FALSE)>0,$D35*VLOOKUP($B35,Mapa_RA_CE!$A:$AD,MATCH(H1,Mapa_RA_CE!$1:$1,0),FALSE),""),"") | I35: =IFERROR(IF(VLOOKUP($B35,Mapa_RA_CE!$A:$AD,MATCH(I1,Mapa_RA_CE!$1:$1,0),FALSE)>0,$D35*VLOOKUP($B35,Mapa_RA_CE!$A:$AD,MATCH(I1,Mapa_RA_CE!$1:$1,0),FALSE),""),"") | J35: =IFERROR(IF(VLOOKUP($B35,Mapa_RA_CE!$A:$AD,MATCH(J1,Mapa_RA_CE!$1:$1,0),FALSE)>0,$D35*VLOOKUP($B35,Mapa_RA_CE!$A:$AD,MATCH(J1,Mapa_RA_CE!$1:$1,0),FALSE),""),"") | K35: =IFERROR(IF(VLOOKUP($B35,Mapa_RA_CE!$A:$AD,MATCH(K1,Mapa_RA_CE!$1:$1,0),FALSE)>0,$D35*VLOOKUP($B35,Mapa_RA_CE!$A:$AD,MATCH(K1,Mapa_RA_CE!$1:$1,0),FALSE),""),"") | L35: =IFERROR(IF(VLOOKUP($B35,Mapa_RA_CE!$A:$AD,MATCH(L1,Mapa_RA_CE!$1:$1,0),FALSE)>0,$D35*VLOOKUP($B35,Mapa_RA_CE!$A:$AD,MATCH(L1,Mapa_RA_CE!$1:$1,0),FALSE),""),"") | M35: =IFERROR(IF(VLOOKUP($B35,Mapa_RA_CE!$A:$AD,MATCH(M1,Mapa_RA_CE!$1:$1,0),FALSE)>0,$D35*VLOOKUP($B35,Mapa_RA_CE!$A:$AD,MATCH(M1,Mapa_RA_CE!$1:$1,0),FALSE),""),"") | ... AC35: =IFERROR(IF(VLOOKUP($B35,Mapa_RA_CE!$A:$AD,MATCH(AC1,Mapa_RA_CE!$1:$1,0),FALSE)>0,$D35*VLOOKUP($B35,Mapa_RA_CE!$A:$AD,MATCH(AC1,Mapa_RA_CE!$1:$1,0),FALSE),""),"")
C36: =IFERROR(VLOOKUP($B36,Mapa_RA_CE!$A:$AD,2,FALSE),"") | F36: =IFERROR(IF(VLOOKUP($B36,Mapa_RA_CE!$A:$AD,MATCH(F1,Mapa_RA_CE!$1:$1,0),FALSE)>0,$D36*VLOOKUP($B36,Mapa_RA_CE!$A:$AD,MATCH(F1,Mapa_RA_CE!$1:$1,0),FALSE),""),"") | G36: =IFERROR(IF(VLOOKUP($B36,Mapa_RA_CE!$A:$AD,MATCH(G1,Mapa_RA_CE!$1:$1,0),FALSE)>0,$D36*VLOOKUP($B36,Mapa_RA_CE!$A:$AD,MATCH(G1,Mapa_RA_CE!$1:$1,0),FALSE),""),"") | H36: =IFERROR(IF(VLOOKUP($B36,Mapa_RA_CE!$A:$AD,MATCH(H1,Mapa_RA_CE!$1:$1,0),FALSE)>0,$D36*VLOOKUP($B36,Mapa_RA_CE!$A:$AD,MATCH(H1,Mapa_RA_CE!$1:$1,0),FALSE),""),"") | I36: =IFERROR(IF(VLOOKUP($B36,Mapa_RA_CE!$A:$AD,MATCH(I1,Mapa_RA_CE!$1:$1,0),FALSE)>0,$D36*VLOOKUP($B36,Mapa_RA_CE!$A:$AD,MATCH(I1,Mapa_RA_CE!$1:$1,0),FALSE),""),"") | J36: =IFERROR(IF(VLOOKUP($B36,Mapa_RA_CE!$A:$AD,MATCH(J1,Mapa_RA_CE!$1:$1,0),FALSE)>0,$D36*VLOOKUP($B36,Mapa_RA_CE!$A:$AD,MATCH(J1,Mapa_RA_CE!$1:$1,0),FALSE),""),"") | K36: =IFERROR(IF(VLOOKUP($B36,Mapa_RA_CE!$A:$AD,MATCH(K1,Mapa_RA_CE!$1:$1,0),FALSE)>0,$D36*VLOOKUP($B36,Mapa_RA_CE!$A:$AD,MATCH(K1,Mapa_RA_CE!$1:$1,0),FALSE),""),"") | L36: =IFERROR(IF(VLOOKUP($B36,Mapa_RA_CE!$A:$AD,MATCH(L1,Mapa_RA_CE!$1:$1,0),FALSE)>0,$D36*VLOOKUP($B36,Mapa_RA_CE!$A:$AD,MATCH(L1,Mapa_RA_CE!$1:$1,0),FALSE),""),"") | M36: =IFERROR(IF(VLOOKUP($B36,Mapa_RA_CE!$A:$AD,MATCH(M1,Mapa_RA_CE!$1:$1,0),FALSE)>0,$D36*VLOOKUP($B36,Mapa_RA_CE!$A:$AD,MATCH(M1,Mapa_RA_CE!$1:$1,0),FALSE),""),"") | ... AC36: =IFERROR(IF(VLOOKUP($B36,Mapa_RA_CE!$A:$AD,MATCH(AC1,Mapa_RA_CE!$1:$1,0),FALSE)>0,$D36*VLOOKUP($B36,Mapa_RA_CE!$A:$AD,MATCH(AC1,Mapa_RA_CE!$1:$1,0),FALSE),""),"")
